File: samples/4h1%_mini/1%.txt
Datapoint no.: 0
 #  Time [s]  Stress [Pa]  Strain [-]
TorqueRatio 1.013052e+00
AngleRatio 9.779039e-01
0 0.000000e+00 -8.849902e-03 -6.660382e-04
1 1.953125e-03 -8.451172e-03 -6.367865e-04
2 3.906250e-03 -8.931901e-03 -6.615379e-04
3 5.859375e-03 -9.150691e-03 -6.907897e-04
4 7.812500e-03 -8.926200e-03 -6.817891e-04
5 9.765625e-03 -9.396609e-03 -6.750386e-04
6 1.171875e-02 -9.876321e-03 -6.637881e-04
7 1.367188e-02 -1.047007e-02 -6.592877e-04
8 1.562500e-02 -1.106721e-02 -6.390366e-04
9 1.757812e-02 -1.167391e-02 -6.547875e-04
10 1.953125e-02 -1.186426e-02 -6.705382e-04
11 2.148438e-02 -1.169193e-02 -6.795388e-04
12 2.343750e-02 -1.174097e-02 -7.087906e-04
13 2.539062e-02 -1.142717e-02 -7.290417e-04
14 2.734375e-02 -1.149509e-02 -7.402922e-04
15 2.929688e-02 -1.148932e-02 -7.695439e-04
16 3.125000e-02 -1.119947e-02 -8.167967e-04
17 3.320312e-02 -1.068898e-02 -8.685497e-04
18 3.515625e-02 -9.609399e-03 -8.955512e-04
19 3.710938e-02 -9.125583e-03 -9.158024e-04
20 3.906250e-02 -9.076463e-03 -9.270529e-04
21 4.101562e-02 -9.288386e-03 -9.135522e-04
22 4.296875e-02 -1.014046e-02 -9.225528e-04
23 4.492188e-02 -1.030430e-02 -9.248028e-04
24 4.687500e-02 -1.059125e-02 -9.428040e-04
25 4.882812e-02 -1.057775e-02 -9.653052e-04
26 5.078125e-02 -1.066644e-02 -9.518046e-04
27 5.273438e-02 -1.135287e-02 -9.405538e-04
28 5.468750e-02 -1.177638e-02 -9.338033e-04
29 5.664062e-02 -1.218030e-02 -9.450542e-04
30 5.859375e-02 -1.240768e-02 -9.428040e-04
31 6.054688e-02 -1.262931e-02 -9.315532e-04
32 6.250000e-02 -1.297302e-02 -9.315532e-04
33 6.445312e-02 -1.353133e-02 -9.360535e-04
34 6.640625e-02 -1.357549e-02 -9.248028e-04
35 6.835938e-02 -1.395794e-02 -9.383037e-04
36 7.031250e-02 -1.413785e-02 -9.270529e-04
37 7.226562e-02 -1.454953e-02 -9.023015e-04
38 7.421875e-02 -1.520559e-02 -9.270529e-04
39 7.617188e-02 -1.494539e-02 -9.698056e-04
40 7.812500e-02 -1.435855e-02 -1.008058e-03
41 8.007812e-02 -1.351587e-02 -1.008058e-03
42 8.203125e-02 -1.359558e-02 -9.923069e-04
43 8.398438e-02 -1.439592e-02 -9.923069e-04
44 8.593750e-02 -1.453746e-02 -1.019308e-03
45 8.789062e-02 -1.432996e-02 -1.095813e-03
46 8.984375e-02 -1.329303e-02 -1.113814e-03
47 9.179688e-02 -1.259824e-02 -1.118314e-03
48 9.375000e-02 -1.247476e-02 -1.100313e-03
49 9.570312e-02 -1.325998e-02 -1.084562e-03
50 9.765625e-02 -1.374834e-02 -1.089062e-03
51 9.960938e-02 -1.397458e-02 -1.107063e-03
52 1.015625e-01 -1.384926e-02 -1.104813e-03
53 1.035156e-01 -1.396340e-02 -1.093562e-03
54 1.054688e-01 -1.427750e-02 -1.082312e-03
55 1.074219e-01 -1.503825e-02 -1.075562e-03
56 1.093750e-01 -1.532362e-02 -1.066561e-03
57 1.113281e-01 -1.562048e-02 -1.053060e-03
58 1.132812e-01 -1.600638e-02 -1.050810e-03
59 1.152344e-01 -1.642202e-02 -1.062061e-03
60 1.171875e-01 -1.609280e-02 -1.111563e-03
61 1.191406e-01 -1.519923e-02 -1.134065e-03
62 1.210938e-01 -1.476134e-02 -1.091313e-03
63 1.230469e-01 -1.554099e-02 -1.050810e-03
64 1.250000e-01 -1.651362e-02 -1.068811e-03
65 1.269531e-01 -1.675528e-02 -1.091313e-03
66 1.289062e-01 -1.620989e-02 -1.113814e-03
67 1.308594e-01 -1.565982e-02 -1.129565e-03
68 1.328125e-01 -1.544103e-02 -1.120564e-03
69 1.347656e-01 -1.559455e-02 -1.091313e-03
70 1.367188e-01 -1.620566e-02 -1.109314e-03
71 1.386719e-01 -1.612894e-02 -1.140815e-03
72 1.406250e-01 -1.558412e-02 -1.190318e-03
73 1.425781e-01 -1.438372e-02 -1.244321e-03
74 1.445312e-01 -1.335743e-02 -1.239821e-03
75 1.464844e-01 -1.338863e-02 -1.201569e-03
76 1.484375e-01 -1.406280e-02 -1.190318e-03
77 1.503906e-01 -1.487247e-02 -1.176817e-03
78 1.523438e-01 -1.525361e-02 -1.199319e-03
79 1.542969e-01 -1.480334e-02 -1.224070e-03
80 1.562500e-01 -1.433990e-02 -1.219570e-03
81 1.582031e-01 -1.454138e-02 -1.174567e-03
82 1.601562e-01 -1.509777e-02 -1.156566e-03
83 1.621094e-01 -1.569273e-02 -1.138565e-03
84 1.640625e-01 -1.628104e-02 -1.125064e-03
85 1.660156e-01 -1.657906e-02 -1.129565e-03
86 1.679688e-01 -1.654492e-02 -1.152066e-03
87 1.699219e-01 -1.609020e-02 -1.147566e-03
88 1.718750e-01 -1.583730e-02 -1.120564e-03
89 1.738281e-01 -1.623929e-02 -1.102563e-03
90 1.757812e-01 -1.695005e-02 -1.075562e-03
91 1.777344e-01 -1.726577e-02 -1.086812e-03
92 1.796875e-01 -1.711457e-02 -1.107063e-03
93 1.816406e-01 -1.652468e-02 -1.116064e-03
94 1.835938e-01 -1.624146e-02 -1.122814e-03
95 1.855469e-01 -1.581029e-02 -1.134065e-03
96 1.875000e-01 -1.554449e-02 -1.113814e-03
97 1.894531e-01 -1.590959e-02 -1.109314e-03
98 1.914062e-01 -1.591205e-02 -1.131815e-03
99 1.933594e-01 -1.546201e-02 -1.129565e-03
100 1.953125e-01 -1.549446e-02 -1.163317e-03
101 1.972656e-01 -1.437424e-02 -1.206069e-03
102 1.992188e-01 -1.326621e-02 -1.221820e-03
103 2.011719e-01 -1.295083e-02 -1.208319e-03
104 2.031250e-01 -1.287759e-02 -1.203819e-03
105 2.050781e-01 -1.307709e-02 -1.174567e-03
106 2.070312e-01 -1.370114e-02 -1.172317e-03
107 2.089844e-01 -1.376474e-02 -1.190318e-03
108 2.109375e-01 -1.344944e-02 -1.183568e-03
109 2.128906e-01 -1.319582e-02 -1.156566e-03
110 2.148438e-01 -1.377262e-02 -1.102563e-03
111 2.167969e-01 -1.463015e-02 -1.064311e-03
112 2.187500e-01 -1.559131e-02 -1.064311e-03
113 2.207031e-01 -1.559058e-02 -1.062061e-03
114 2.226562e-01 -1.527410e-02 -1.095813e-03
115 2.246094e-01 -1.454229e-02 -1.095813e-03
116 2.265625e-01 -1.402366e-02 -1.071061e-03
117 2.285156e-01 -1.427238e-02 -1.057561e-03
118 2.304688e-01 -1.452376e-02 -1.035059e-03
119 2.324219e-01 -1.496384e-02 -1.019308e-03
120 2.343750e-01 -1.488494e-02 -1.032809e-03
121 2.363281e-01 -1.432991e-02 -1.044060e-03
122 2.382812e-01 -1.397177e-02 -1.050810e-03
123 2.402344e-01 -1.346685e-02 -1.048560e-03
124 2.421875e-01 -1.328601e-02 -1.059811e-03
125 2.441406e-01 -1.279030e-02 -1.066561e-03
126 2.460938e-01 -1.246172e-02 -1.071061e-03
127 2.480469e-01 -1.221457e-02 -1.091313e-03
128 2.500000e-01 -1.147336e-02 -1.084562e-03
129 2.519531e-01 -1.150730e-02 -1.102563e-03
130 2.539062e-01 -1.061926e-02 -1.095813e-03
131 2.558594e-01 -1.064023e-02 -1.080062e-03
132 2.578125e-01 -1.083010e-02 -1.039560e-03
133 2.597656e-01 -1.144361e-02 -1.023808e-03
134 2.617188e-01 -1.139338e-02 -1.017058e-03
135 2.636719e-01 -1.164096e-02 -1.003557e-03
136 2.656250e-01 -1.145624e-02 -9.990571e-04
137 2.675781e-01 -1.121490e-02 -9.855564e-04
138 2.695312e-01 -1.133634e-02 -9.338033e-04
139 2.714844e-01 -1.194123e-02 -9.135522e-04
140 2.734375e-01 -1.232069e-02 -8.798002e-04
141 2.753906e-01 -1.270352e-02 -8.820503e-04
142 2.773438e-01 -1.227834e-02 -9.090520e-04
143 2.792969e-01 -1.141862e-02 -9.158024e-04
144 2.812500e-01 -1.100484e-02 -9.023015e-04
145 2.832031e-01 -1.073315e-02 -8.843005e-04
146 2.851562e-01 -1.067009e-02 -8.640494e-04
147 2.871094e-01 -1.075434e-02 -8.707998e-04
148 2.890625e-01 -1.050820e-02 -8.843005e-04
149 2.910156e-01 -9.796946e-03 -9.158024e-04
150 2.929688e-01 -8.714780e-03 -9.158024e-04
151 2.949219e-01 -8.269087e-03 -8.978015e-04
152 2.968750e-01 -8.221369e-03 -8.707998e-04
153 2.988281e-01 -8.603273e-03 -8.640494e-04
154 3.007812e-01 -8.821962e-03 -8.595490e-04
155 3.027344e-01 -8.297334e-03 -8.978015e-04
156 3.046875e-01 -7.154337e-03 -9.023015e-04
157 3.066406e-01 -6.598891e-03 -9.113021e-04
158 3.085938e-01 -6.078847e-03 -8.910510e-04
159 3.105469e-01 -6.271069e-03 -8.550488e-04
160 3.125000e-01 -6.599705e-03 -8.415481e-04
161 3.144531e-01 -6.740182e-03 -8.055462e-04
162 3.164062e-01 -6.919388e-03 -7.942954e-04
163 3.183594e-01 -6.865975e-03 -7.717942e-04
164 3.203125e-01 -7.192743e-03 -7.312919e-04
165 3.222656e-01 -7.472928e-03 -6.930396e-04
166 3.242188e-01 -7.703829e-03 -6.907897e-04
167 3.261719e-01 -7.724821e-03 -6.795388e-04
168 3.281250e-01 -7.506351e-03 -6.705382e-04
169 3.300781e-01 -7.054830e-03 -6.502871e-04
170 3.320312e-01 -7.234105e-03 -6.390366e-04
171 3.339844e-01 -7.007489e-03 -6.547875e-04
172 3.359375e-01 -6.208046e-03 -6.592877e-04
173 3.378906e-01 -5.616867e-03 -6.435367e-04
174 3.398438e-01 -5.380839e-03 -6.232855e-04
175 3.417969e-01 -5.351232e-03 -6.097849e-04
176 3.437500e-01 -5.567699e-03 -5.962842e-04
177 3.457031e-01 -5.172284e-03 -6.187856e-04
178 3.476562e-01 -4.130933e-03 -6.165353e-04
179 3.496094e-01 -3.696938e-03 -6.142852e-04
180 3.515625e-01 -3.527605e-03 -6.030345e-04
181 3.535156e-01 -3.227534e-03 -5.917840e-04
182 3.554688e-01 -2.928714e-03 -5.895338e-04
183 3.574219e-01 -2.602940e-03 -5.827833e-04
184 3.593750e-01 -2.538027e-03 -5.737827e-04
185 3.613281e-01 -2.181510e-03 -5.760328e-04
186 3.632812e-01 -1.928735e-03 -5.445312e-04
187 3.652344e-01 -1.786894e-03 -5.445312e-04
188 3.671875e-01 -1.528092e-03 -5.400309e-04
189 3.691406e-01 -1.424533e-03 -4.815274e-04
190 3.710938e-01 -1.971475e-03 -4.477756e-04
191 3.730469e-01 -2.090738e-03 -4.297747e-04
192 3.750000e-01 -2.190427e-03 -4.410252e-04
193 3.769531e-01 -1.959608e-03 -4.050233e-04
194 3.789062e-01 -1.690401e-03 -3.915223e-04
195 3.808594e-01 -1.623345e-03 -3.487699e-04
196 3.828125e-01 -2.097999e-03 -3.217683e-04
197 3.847656e-01 -2.075548e-03 -3.397693e-04
198 3.867188e-01 -1.596529e-03 -3.577705e-04
199 3.886719e-01 -6.413132e-04 -3.802718e-04
200 3.906250e-01 4.623790e-04 -3.712712e-04
201 3.925781e-01 9.790770e-04 -3.555204e-04
202 3.945312e-01 1.173470e-03 -3.375194e-04
203 3.964844e-01 1.163882e-03 -3.645207e-04
204 3.984375e-01 2.181064e-03 -3.825220e-04
205 4.003906e-01 2.724737e-03 -3.510201e-04
206 4.023438e-01 2.831505e-03 -3.397693e-04
207 4.042969e-01 3.028023e-03 -3.195182e-04
208 4.062500e-01 2.839040e-03 -2.812661e-04
209 4.082031e-01 2.613283e-03 -2.992670e-04
210 4.101562e-01 3.091827e-03 -2.947667e-04
211 4.121094e-01 3.605084e-03 -2.857663e-04
212 4.140625e-01 3.770584e-03 -2.677653e-04
213 4.160156e-01 3.782585e-03 -2.520144e-04
214 4.179688e-01 4.191042e-03 -2.520144e-04
215 4.199219e-01 4.390013e-03 -2.115121e-04
216 4.218750e-01 4.270925e-03 -1.620093e-04
217 4.238281e-01 3.649836e-03 -1.305075e-04
218 4.257812e-01 3.224015e-03 -1.057561e-04
219 4.277344e-01 3.186695e-03 -1.080062e-04
220 4.296875e-01 3.628466e-03 -9.675555e-05
221 4.316406e-01 3.899891e-03 -5.850334e-05
222 4.335938e-01 3.670523e-03 -1.800103e-05
223 4.355469e-01 3.406090e-03 -1.575090e-05
224 4.375000e-01 3.658533e-03 -1.350077e-05
225 4.394531e-01 4.085888e-03 -4.275245e-05
226 4.414062e-01 5.177979e-03 -2.925167e-05
227 4.433594e-01 5.728736e-03 -3.825220e-05
228 4.453125e-01 6.371878e-03 -3.600207e-05
229 4.472656e-01 6.683031e-03 -3.150182e-05
230 4.492188e-01 7.039735e-03 -2.250129e-05
231 4.511719e-01 7.207830e-03 -2.925167e-05
232 4.531250e-01 7.921544e-03 -1.800103e-05
233 4.550781e-01 8.170266e-03 -2.700155e-05
234 4.570312e-01 8.653846e-03 -2.700155e-05
235 4.589844e-01 9.174188e-03 -1.800103e-05
236 4.609375e-01 9.472625e-03 6.750386e-06
237 4.628906e-01 9.325577e-03 3.600207e-05
238 4.648438e-01 9.115505e-03 7.650437e-05
239 4.667969e-01 8.508082e-03 8.325475e-05
240 4.687500e-01 8.818442e-03 8.325475e-05
241 4.707031e-01 9.252233e-03 7.650437e-05
242 4.726562e-01 9.701200e-03 1.170067e-04
243 4.746094e-01 9.327105e-03 1.755100e-04
244 4.765625e-01 8.713966e-03 1.867607e-04
245 4.785156e-01 8.814866e-03 2.025116e-04
246 4.804688e-01 8.580253e-03 2.182625e-04
247 4.824219e-01 8.952189e-03 2.272630e-04
248 4.843750e-01 9.288001e-03 2.677653e-04
249 4.863281e-01 9.013125e-03 2.970169e-04
250 4.882812e-01 8.757251e-03 3.285188e-04
251 4.902344e-01 8.438019e-03 3.375194e-04
252 4.921875e-01 8.527257e-03 3.240185e-04
253 4.941406e-01 9.444159e-03 2.970169e-04
254 4.960938e-01 1.050708e-02 2.812661e-04
255 4.980469e-01 1.134386e-02 2.655152e-04
256 5.000000e-01 1.196836e-02 2.677653e-04
257 5.019531e-01 1.248878e-02 2.385136e-04
258 5.039062e-01 1.338641e-02 2.677653e-04
259 5.058594e-01 1.330899e-02 2.835162e-04
260 5.078125e-01 1.337368e-02 2.902666e-04
261 5.097656e-01 1.349532e-02 2.722656e-04
262 5.117188e-01 1.403556e-02 2.902666e-04
263 5.136719e-01 1.436818e-02 2.925167e-04
264 5.156250e-01 1.446468e-02 3.330191e-04
265 5.175781e-01 1.403787e-02 3.735214e-04
266 5.195312e-01 1.342901e-02 3.465198e-04
267 5.214844e-01 1.405246e-02 3.442696e-04
268 5.234375e-01 1.441390e-02 3.577705e-04
269 5.253906e-01 1.473357e-02 3.892721e-04
270 5.273438e-01 1.454958e-02 4.320248e-04
271 5.292969e-01 1.380821e-02 4.995287e-04
272 5.312500e-01 1.294115e-02 5.062788e-04
273 5.332031e-01 1.269553e-02 5.152795e-04
274 5.351562e-01 1.282043e-02 5.400309e-04
275 5.371094e-01 1.262661e-02 5.490315e-04
276 5.390625e-01 1.313985e-02 5.625322e-04
277 5.410156e-01 1.334581e-02 5.670325e-04
278 5.429688e-01 1.344183e-02 5.580318e-04
279 5.449219e-01 1.400006e-02 5.602820e-04
280 5.468750e-01 1.427328e-02 5.535316e-04
281 5.488281e-01 1.482015e-02 5.445312e-04
282 5.507812e-01 1.549851e-02 5.130293e-04
283 5.527344e-01 1.630846e-02 5.130293e-04
284 5.546875e-01 1.666449e-02 5.130293e-04
285 5.566406e-01 1.726457e-02 5.130293e-04
286 5.585938e-01 1.727465e-02 5.197798e-04
287 5.605469e-01 1.725930e-02 5.265302e-04
288 5.625000e-01 1.747847e-02 5.197798e-04
289 5.644531e-01 1.802822e-02 5.220299e-04
290 5.664062e-01 1.801317e-02 5.355306e-04
291 5.683594e-01 1.802371e-02 5.355306e-04
292 5.703125e-01 1.829658e-02 5.872836e-04
293 5.722656e-01 1.723290e-02 6.390366e-04
294 5.742188e-01 1.647401e-02 6.480369e-04
295 5.761719e-01 1.635078e-02 6.367865e-04
296 5.781250e-01 1.654530e-02 6.570376e-04
297 5.800781e-01 1.666956e-02 6.570376e-04
298 5.820312e-01 1.699772e-02 6.817891e-04
299 5.839844e-01 1.683985e-02 7.087906e-04
300 5.859375e-01 1.642897e-02 7.425423e-04
301 5.878906e-01 1.616039e-02 7.492928e-04
302 5.898438e-01 1.608755e-02 7.515430e-04
303 5.917969e-01 1.614391e-02 7.605436e-04
304 5.937500e-01 1.629496e-02 7.470427e-04
305 5.957031e-01 1.672441e-02 7.492928e-04
306 5.976562e-01 1.679244e-02 7.762944e-04
307 5.996094e-01 1.679590e-02 7.627935e-04
308 6.015625e-01 1.716648e-02 7.290417e-04
309 6.035156e-01 1.785693e-02 6.975398e-04
310 6.054688e-01 1.900235e-02 6.615379e-04
311 6.074219e-01 1.991651e-02 6.255357e-04
312 6.093750e-01 2.073820e-02 6.547875e-04
313 6.113281e-01 2.042579e-02 6.390366e-04
314 6.132812e-01 2.085974e-02 6.570376e-04
315 6.152344e-01 2.049352e-02 6.817891e-04
316 6.171875e-01 2.001250e-02 6.952897e-04
317 6.191406e-01 1.986311e-02 6.840392e-04
318 6.210938e-01 2.003362e-02 6.840392e-04
319 6.230469e-01 2.008845e-02 7.155408e-04
320 6.250000e-01 1.974423e-02 7.312919e-04
321 6.269531e-01 1.933932e-02 7.402922e-04
322 6.289062e-01 1.910479e-02 7.695439e-04
323 6.308594e-01 1.863939e-02 7.627935e-04
324 6.328125e-01 1.879099e-02 7.672938e-04
325 6.347656e-01 1.872181e-02 7.942954e-04
326 6.367188e-01 1.859300e-02 8.122963e-04
327 6.386719e-01 1.815781e-02 8.482985e-04
328 6.406250e-01 1.729324e-02 8.753001e-04
329 6.425781e-01 1.700228e-02 8.572989e-04
330 6.445312e-01 1.716538e-02 8.550488e-04
331 6.464844e-01 1.741184e-02 8.482985e-04
332 6.484375e-01 1.779518e-02 8.325475e-04
333 6.503906e-01 1.828520e-02 8.257973e-04
334 6.523438e-01 1.869288e-02 8.347977e-04
335 6.542969e-01 1.824844e-02 8.235471e-04
336 6.562500e-01 1.869724e-02 8.100462e-04
337 6.582031e-01 1.896582e-02 7.740443e-04
338 6.601562e-01 1.968548e-02 7.357922e-04
339 6.621094e-01 2.065155e-02 7.267916e-04
340 6.640625e-01 2.081654e-02 7.222913e-04
341 6.660156e-01 2.078892e-02 7.267916e-04
342 6.679688e-01 2.083329e-02 7.222913e-04
343 6.699219e-01 2.074516e-02 7.245414e-04
344 6.718750e-01 2.050020e-02 7.380423e-04
345 6.738281e-01 2.033541e-02 7.312919e-04
346 6.757812e-01 2.043531e-02 7.447926e-04
347 6.777344e-01 1.985084e-02 7.582934e-04
348 6.796875e-01 1.944046e-02 8.122963e-04
349 6.816406e-01 1.849026e-02 8.437983e-04
350 6.835938e-01 1.776014e-02 8.662996e-04
351 6.855469e-01 1.702964e-02 8.437983e-04
352 6.875000e-01 1.725947e-02 8.212969e-04
353 6.894531e-01 1.777767e-02 8.010459e-04
354 6.914062e-01 1.836574e-02 8.010459e-04
355 6.933594e-01 1.850198e-02 8.032960e-04
356 6.953125e-01 1.797972e-02 8.572989e-04
357 6.972656e-01 1.702044e-02 8.550488e-04
358 6.992188e-01 1.703487e-02 8.437983e-04
359 7.011719e-01 1.691186e-02 8.257973e-04
360 7.031250e-01 1.740323e-02 7.897951e-04
361 7.050781e-01 1.812505e-02 7.920452e-04
362 7.070312e-01 1.792083e-02 8.010459e-04
363 7.089844e-01 1.779217e-02 7.875449e-04
364 7.109375e-01 1.794916e-02 7.695439e-04
365 7.128906e-01 1.788545e-02 7.177910e-04
366 7.148438e-01 1.869944e-02 6.975398e-04
367 7.167969e-01 1.935811e-02 6.727884e-04
368 7.187500e-01 1.980164e-02 6.660382e-04
369 7.207031e-01 1.977686e-02 7.087906e-04
370 7.226562e-01 1.880728e-02 7.380423e-04
371 7.246094e-01 1.772225e-02 7.560433e-04
372 7.265625e-01 1.680778e-02 7.537932e-04
373 7.285156e-01 1.675232e-02 7.177910e-04
374 7.304688e-01 1.734103e-02 7.110408e-04
375 7.324219e-01 1.729411e-02 7.357922e-04
376 7.343750e-01 1.676806e-02 7.650437e-04
377 7.363281e-01 1.597085e-02 7.987957e-04
378 7.382812e-01 1.491344e-02 8.077963e-04
379 7.402344e-01 1.443733e-02 7.807948e-04
380 7.421875e-01 1.487939e-02 7.447926e-04
381 7.441406e-01 1.542026e-02 7.380423e-04
382 7.460938e-01 1.560892e-02 7.245414e-04
383 7.480469e-01 1.577987e-02 7.222913e-04
384 7.500000e-01 1.544043e-02 7.200411e-04
385 7.519531e-01 1.520791e-02 7.065404e-04
386 7.539062e-01 1.526048e-02 6.840392e-04
387 7.558594e-01 1.555935e-02 6.187856e-04
388 7.578125e-01 1.654048e-02 5.850334e-04
389 7.597656e-01 1.717742e-02 5.692827e-04
390 7.617188e-01 1.749017e-02 5.760328e-04
391 7.636719e-01 1.672030e-02 6.097849e-04
392 7.656250e-01 1.576315e-02 5.940341e-04
393 7.675781e-01 1.559821e-02 5.647824e-04
394 7.695312e-01 1.574295e-02 5.152795e-04
395 7.714844e-01 1.670049e-02 4.860277e-04
396 7.734375e-01 1.708712e-02 4.860277e-04
397 7.753906e-01 1.679785e-02 5.085290e-04
398 7.773438e-01 1.594146e-02 5.175296e-04
399 7.792969e-01 1.542662e-02 5.265302e-04
400 7.812500e-01 1.469339e-02 5.467813e-04
401 7.832031e-01 1.397928e-02 5.400309e-04
402 7.851562e-01 1.373020e-02 5.242801e-04
403 7.871094e-01 1.348293e-02 5.490315e-04
404 7.890625e-01 1.281243e-02 5.805331e-04
405 7.910156e-01 1.210618e-02 6.030345e-04
406 7.929688e-01 1.095726e-02 6.187856e-04
407 7.949219e-01 1.020693e-02 6.075347e-04
408 7.968750e-01 1.033110e-02 5.445312e-04
409 7.988281e-01 1.116909e-02 4.905281e-04
410 8.007812e-01 1.208262e-02 4.770274e-04
411 8.027344e-01 1.236682e-02 4.860277e-04
412 8.046875e-01 1.184927e-02 5.107792e-04
413 8.066406e-01 1.074704e-02 5.332804e-04
414 8.085938e-01 1.017060e-02 4.905281e-04
415 8.105469e-01 1.065308e-02 4.320248e-04
416 8.125000e-01 1.128575e-02 4.095233e-04
417 8.144531e-01 1.166347e-02 3.847721e-04
418 8.164062e-01 1.198876e-02 3.870223e-04
419 8.183594e-01 1.135605e-02 3.982728e-04
420 8.203125e-01 1.081583e-02 3.735214e-04
421 8.222656e-01 1.070988e-02 3.532702e-04
422 8.242188e-01 1.067363e-02 3.352693e-04
423 8.261719e-01 1.083352e-02 3.240185e-04
424 8.281250e-01 1.079410e-02 2.992670e-04
425 8.300781e-01 1.062116e-02 3.172680e-04
426 8.320312e-01 1.002272e-02 3.352693e-04
427 8.339844e-01 9.388829e-03 3.465198e-04
428 8.359375e-01 8.464735e-03 3.397693e-04
429 8.378906e-01 8.063094e-03 3.240185e-04
430 8.398438e-01 7.900636e-03 2.925167e-04
431 8.417969e-01 8.148755e-03 2.947667e-04
432 8.437500e-01 8.004762e-03 3.172680e-04
433 8.457031e-01 7.361195e-03 3.420194e-04
434 8.476562e-01 6.218643e-03 3.532702e-04
435 8.496094e-01 5.322751e-03 3.262686e-04
436 8.515625e-01 5.594721e-03 2.700154e-04
437 8.535156e-01 6.363245e-03 2.115121e-04
438 8.554688e-01 7.214493e-03 1.935111e-04
439 8.574219e-01 7.388763e-03 1.800103e-04
440 8.593750e-01 7.312382e-03 1.665095e-04
441 8.613281e-01 6.894855e-03 1.575090e-04
442 8.632812e-01 6.767605e-03 1.215069e-04
443 8.652344e-01 7.003351e-03 8.550491e-05
444 8.671875e-01 7.038870e-03 4.500258e-05
445 8.691406e-01 7.631045e-03 3.375194e-05
446 8.710938e-01 7.589213e-03 4.950284e-05
447 8.730469e-01 6.685023e-03 8.550491e-05
448 8.750000e-01 5.601091e-03 8.325475e-05
449 8.769531e-01 5.105950e-03 4.725271e-05
450 8.789062e-01 4.862780e-03 1.575090e-05
451 8.808594e-01 5.262086e-03 -2.475141e-05
452 8.828125e-01 5.636378e-03 -3.150182e-05
453 8.847656e-01 5.410140e-03 2.250129e-06
454 8.867188e-01 4.453993e-03 4.500258e-06
455 8.886719e-01 3.719141e-03 1.800103e-05
456 8.906250e-01 2.771846e-03 3.375194e-05
457 8.925781e-01 2.060554e-03 6.750386e-06
458 8.945312e-01 2.126480e-03 -6.750386e-06
459 8.964844e-01 1.968364e-03 -4.500258e-06
460 8.984375e-01 1.647319e-03 6.750386e-06
461 9.003906e-01 8.634910e-04 1.125064e-05
462 9.023438e-01 2.586049e-04 1.125064e-05
463 9.042969e-01 -9.909561e-05 -2.700155e-05
464 9.062500e-01 2.514773e-04 -7.875449e-05
465 9.082031e-01 6.811604e-04 -1.012558e-04
466 9.101562e-01 1.073343e-03 -1.327576e-04
467 9.121094e-01 1.543808e-03 -1.530088e-04
468 9.140625e-01 1.261083e-03 -1.552589e-04
469 9.160156e-01 9.775449e-04 -1.755100e-04
470 9.179688e-01 8.828711e-04 -2.047617e-04
471 9.199219e-01 8.892200e-04 -2.632651e-04
472 9.218750e-01 1.280834e-03 -2.722656e-04
473 9.238281e-01 1.660520e-03 -3.195182e-04
474 9.257812e-01 1.795460e-03 -2.992670e-04
475 9.277344e-01 1.025660e-03 -2.880165e-04
476 9.296875e-01 4.146795e-04 -2.812661e-04
477 9.316406e-01 -4.839258e-04 -2.925167e-04
478 9.335938e-01 -9.341534e-04 -3.217683e-04
479 9.355469e-01 -6.473594e-04 -3.622709e-04
480 9.375000e-01 -1.978243e-04 -3.510201e-04
481 9.394531e-01 -8.695247e-04 -3.195182e-04
482 9.414062e-01 -1.703918e-03 -2.902666e-04
483 9.433594e-01 -2.997542e-03 -2.970169e-04
484 9.453125e-01 -3.744637e-03 -2.947667e-04
485 9.472656e-01 -3.981993e-03 -3.240185e-04
486 9.492188e-01 -3.592734e-03 -3.397693e-04
487 9.511719e-01 -4.108529e-03 -3.015172e-04
488 9.531250e-01 -4.933720e-03 -2.947667e-04
489 9.550781e-01 -5.543622e-03 -2.925167e-04
490 9.570312e-01 -6.161375e-03 -3.015172e-04
491 9.589844e-01 -6.399186e-03 -3.555204e-04
492 9.609375e-01 -5.724457e-03 -3.915223e-04
493 9.628906e-01 -5.479892e-03 -4.027731e-04
494 9.648438e-01 -5.235377e-03 -4.117734e-04
495 9.667969e-01 -5.241480e-03 -4.702769e-04
496 9.687500e-01 -4.829717e-03 -4.815274e-04
497 9.707031e-01 -4.892583e-03 -5.377808e-04
498 9.726562e-01 -4.148837e-03 -5.490315e-04
499 9.746094e-01 -4.226704e-03 -5.557817e-04
500 9.765625e-01 -4.769830e-03 -5.782830e-04
501 9.785156e-01 -4.774611e-03 -5.872836e-04
502 9.804688e-01 -4.787082e-03 -5.805331e-04
503 9.824219e-01 -5.476343e-03 -5.760328e-04
504 9.843750e-01 -5.804388e-03 -5.805331e-04
505 9.863281e-01 -6.583584e-03 -6.052846e-04
506 9.882812e-01 -6.633514e-03 -5.917840e-04
507 9.902344e-01 -6.902433e-03 -6.165353e-04
508 9.921875e-01 -7.000105e-03 -6.142852e-04
509 9.941406e-01 -7.388728e-03 -6.120350e-04
510 9.960938e-01 -8.022642e-03 -6.120350e-04
511 9.980469e-01 -8.298878e-03 -6.187856e-04
Datapoint no.: 1
 #  Time [s]  Stress [Pa]  Strain [-]
TorqueRatio 1.053414e+00
AngleRatio 1.018193e+00
0 0.000000e+00 -1.523705e-02 -1.030846e-03
1 1.953125e-03 -1.583751e-02 -9.933606e-04
2 3.906250e-03 -1.644900e-02 -9.652466e-04
3 5.859375e-03 -1.642004e-02 -9.863323e-04
4 7.812500e-03 -1.552409e-02 -1.016789e-03
5 9.765625e-03 -1.492429e-02 -1.026160e-03
6 1.171875e-02 -1.342813e-02 -1.028503e-03
7 1.367188e-02 -1.320040e-02 -1.026160e-03
8 1.562500e-02 -1.296696e-02 -9.933606e-04
9 1.757812e-02 -1.308948e-02 -9.816466e-04
10 1.953125e-02 -1.285900e-02 -9.933606e-04
11 2.148438e-02 -1.269858e-02 -9.839894e-04
12 2.343750e-02 -1.207340e-02 -1.005075e-03
13 2.539062e-02 -1.137035e-02 -9.066759e-04
14 2.734375e-02 -1.238897e-02 -8.738762e-04
15 2.929688e-02 -1.330507e-02 -8.410768e-04
16 3.125000e-02 -1.339861e-02 -8.551336e-04
17 3.320312e-02 -1.266191e-02 -8.551336e-04
18 3.515625e-02 -1.239517e-02 -8.551336e-04
19 3.710938e-02 -1.176043e-02 -8.738762e-04
20 3.906250e-02 -1.099869e-02 -8.293625e-04
21 4.101562e-02 -1.133299e-02 -7.778201e-04
22 4.296875e-02 -1.185713e-02 -7.497061e-04
23 4.492188e-02 -1.198465e-02 -7.520490e-04
24 4.687500e-02 -1.167763e-02 -7.403350e-04
25 4.882812e-02 -1.121198e-02 -7.379921e-04
26 5.078125e-02 -1.083276e-02 -7.262778e-04
27 5.273438e-02 -1.038865e-02 -6.934783e-04
28 5.468750e-02 -1.049279e-02 -7.192495e-04
29 5.664062e-02 -9.526471e-03 -7.075352e-04
30 5.859375e-02 -9.224197e-03 -7.051923e-04
31 6.054688e-02 -8.428896e-03 -7.215921e-04
32 6.250000e-02 -7.839040e-03 -7.262778e-04
33 6.445312e-02 -7.208571e-03 -7.473633e-04
34 6.640625e-02 -5.933108e-03 -7.450204e-04
35 6.835938e-02 -5.872275e-03 -7.169066e-04
36 7.031250e-02 -5.939697e-03 -6.559929e-04
37 7.226562e-02 -6.322203e-03 -6.442789e-04
38 7.421875e-02 -6.576974e-03 -6.419360e-04
39 7.617188e-02 -5.779627e-03 -6.372503e-04
40 7.812500e-02 -5.366742e-03 -6.606786e-04
41 8.007812e-02 -4.813931e-03 -6.161649e-04
42 8.203125e-02 -4.920369e-03 -5.716511e-04
43 8.398438e-02 -5.407745e-03 -5.341657e-04
44 8.593750e-02 -5.553654e-03 -5.154230e-04
45 8.789062e-02 -5.412529e-03 -5.083944e-04
46 8.984375e-02 -5.288207e-03 -4.919947e-04
47 9.179688e-02 -5.018063e-03 -4.709093e-04
48 9.375000e-02 -4.950847e-03 -4.287381e-04
49 9.570312e-02 -5.142993e-03 -3.748532e-04
50 9.765625e-02 -5.507502e-03 -3.514249e-04
51 9.960938e-02 -5.754475e-03 -3.256537e-04
52 1.015625e-01 -5.490975e-03 -3.420534e-04
53 1.035156e-01 -4.277041e-03 -3.607961e-04
54 1.054688e-01 -3.607271e-03 -3.537674e-04
55 1.074219e-01 -2.964989e-03 -3.467392e-04
56 1.093750e-01 -2.175063e-03 -3.350249e-04
57 1.113281e-01 -2.033087e-03 -2.998825e-04
58 1.132812e-01 -2.161980e-03 -3.022253e-04
59 1.152344e-01 -1.555221e-03 -3.115966e-04
60 1.171875e-01 -8.516537e-04 -2.998825e-04
61 1.191406e-01 4.694657e-05 -2.881683e-04
62 1.210938e-01 -2.150204e-05 -2.951968e-04
63 1.230469e-01 3.903848e-04 -2.436545e-04
64 1.250000e-01 7.826612e-05 -2.108549e-04
65 1.269531e-01 1.423983e-04 -2.108549e-04
66 1.289062e-01 3.884124e-04 -2.295975e-04
67 1.308594e-01 2.001922e-03 -2.553687e-04
68 1.328125e-01 2.597809e-03 -2.483402e-04
69 1.347656e-01 3.153868e-03 -2.085120e-04
70 1.367188e-01 2.984577e-03 -1.569697e-04
71 1.386719e-01 2.562264e-03 -1.382271e-04
72 1.406250e-01 2.262360e-03 -9.371329e-05
73 1.425781e-01 2.117054e-03 -8.668476e-05
74 1.445312e-01 2.619486e-03 -7.497061e-05
75 1.464844e-01 2.790375e-03 -5.154231e-05
76 1.484375e-01 3.079275e-03 -2.108549e-05
77 1.503906e-01 3.041176e-03 2.342832e-06
78 1.523438e-01 2.918320e-03 2.577115e-05
79 1.542969e-01 3.205515e-03 3.982815e-05
80 1.562500e-01 3.681931e-03 1.874265e-05
81 1.582031e-01 4.721827e-03 9.371329e-06
82 1.601562e-01 5.562604e-03 4.217098e-05
83 1.621094e-01 5.304201e-03 6.794212e-05
84 1.640625e-01 5.309216e-03 1.124559e-04
85 1.660156e-01 4.793072e-03 1.569697e-04
86 1.679688e-01 4.658591e-03 1.780552e-04
87 1.699219e-01 4.866177e-03 1.522840e-04
88 1.718750e-01 6.256309e-03 1.358842e-04
89 1.738281e-01 7.235049e-03 1.382271e-04
90 1.757812e-01 7.434948e-03 1.522840e-04
91 1.777344e-01 7.639759e-03 1.944550e-04
92 1.796875e-01 7.328004e-03 1.827409e-04
93 1.816406e-01 8.048009e-03 1.944550e-04
94 1.835938e-01 8.532705e-03 2.155405e-04
95 1.855469e-01 8.813578e-03 2.108549e-04
96 1.875000e-01 9.168413e-03 2.342832e-04
97 1.894531e-01 9.274619e-03 2.811398e-04
98 1.914062e-01 9.085948e-03 3.162823e-04
99 1.933594e-01 8.661052e-03 3.326820e-04
100 1.953125e-01 8.897640e-03 3.467392e-04
101 1.972656e-01 9.269621e-03 3.490821e-04
102 1.992188e-01 9.823472e-03 3.373677e-04
103 2.011719e-01 1.058231e-02 3.233109e-04
104 2.031250e-01 1.150533e-02 3.561103e-04
105 2.050781e-01 1.138169e-02 3.959387e-04
106 2.070312e-01 1.113063e-02 4.451381e-04
107 2.089844e-01 1.048958e-02 4.404524e-04
108 2.109375e-01 1.103914e-02 4.334238e-04
109 2.128906e-01 1.203970e-02 3.935958e-04
110 2.148438e-01 1.349479e-02 3.935958e-04
111 2.167969e-01 1.356952e-02 4.263952e-04
112 2.187500e-01 1.324130e-02 4.732521e-04
113 2.207031e-01 1.277236e-02 5.107374e-04
114 2.226562e-01 1.263432e-02 5.013659e-04
115 2.246094e-01 1.327446e-02 4.943376e-04
116 2.265625e-01 1.428216e-02 4.755950e-04
117 2.285156e-01 1.505338e-02 4.849661e-04
118 2.304688e-01 1.505573e-02 5.294799e-04
119 2.324219e-01 1.517467e-02 5.599368e-04
120 2.343750e-01 1.442395e-02 5.974220e-04
121 2.363281e-01 1.375645e-02 5.974220e-04
122 2.382812e-01 1.467152e-02 6.021077e-04
123 2.402344e-01 1.513428e-02 6.231935e-04
124 2.421875e-01 1.532970e-02 6.442789e-04
125 2.441406e-01 1.549526e-02 6.794212e-04
126 2.460938e-01 1.464578e-02 7.145638e-04
127 2.480469e-01 1.399466e-02 7.543918e-04
128 2.500000e-01 1.390398e-02 7.590775e-04
129 2.519531e-01 1.458761e-02 7.286206e-04
130 2.539062e-01 1.562648e-02 7.075352e-04
131 2.558594e-01 1.664304e-02 7.239350e-04
132 2.578125e-01 1.704817e-02 7.731344e-04
133 2.597656e-01 1.657616e-02 7.543918e-04
134 2.617188e-01 1.687972e-02 7.918773e-04
135 2.636719e-01 1.673294e-02 7.801630e-04
136 2.656250e-01 1.719350e-02 7.731344e-04
137 2.675781e-01 1.783934e-02 8.082771e-04
138 2.695312e-01 1.770770e-02 7.965628e-04
139 2.714844e-01 1.796309e-02 8.317053e-04
140 2.734375e-01 1.799442e-02 8.410768e-04
141 2.753906e-01 1.819450e-02 8.410768e-04
142 2.773438e-01 1.829702e-02 8.363911e-04
143 2.792969e-01 1.901035e-02 8.223339e-04
144 2.812500e-01 1.991478e-02 8.012484e-04
145 2.832031e-01 2.055582e-02 8.270196e-04
146 2.851562e-01 2.061537e-02 8.199911e-04
147 2.871094e-01 2.021000e-02 8.902760e-04
148 2.890625e-01 1.905308e-02 9.394754e-04
149 2.910156e-01 1.836167e-02 9.746180e-04
150 2.929688e-01 1.822726e-02 9.675894e-04
151 2.949219e-01 1.895228e-02 9.465041e-04
152 2.968750e-01 1.958367e-02 9.465041e-04
153 2.988281e-01 2.010525e-02 9.652466e-04
154 3.007812e-01 1.960642e-02 9.816466e-04
155 3.027344e-01 2.004380e-02 9.957035e-04
156 3.046875e-01 1.996513e-02 9.863323e-04
157 3.066406e-01 2.032686e-02 9.933606e-04
158 3.085938e-01 2.081131e-02 9.769610e-04
159 3.105469e-01 2.118455e-02 9.933606e-04
160 3.125000e-01 2.096175e-02 1.005075e-03
161 3.144531e-01 2.085797e-02 1.049589e-03
162 3.164062e-01 2.051386e-02 1.070674e-03
163 3.183594e-01 2.017587e-02 1.073017e-03
164 3.203125e-01 2.037566e-02 1.047246e-03
165 3.222656e-01 2.142209e-02 1.021475e-03
166 3.242188e-01 2.258673e-02 9.863323e-04
167 3.261719e-01 2.349331e-02 9.839894e-04
168 3.281250e-01 2.326198e-02 1.027995e-03
169 3.300781e-01 2.232304e-02 1.065988e-03
170 3.320312e-01 2.194353e-02 1.061303e-03
171 3.339844e-01 2.221635e-02 1.049589e-03
172 3.359375e-01 2.244802e-02 1.054274e-03
173 3.378906e-01 2.290747e-02 1.068331e-03
174 3.398438e-01 2.287618e-02 1.112845e-03
175 3.417969e-01 2.176874e-02 1.140959e-03
176 3.437500e-01 2.139349e-02 1.133931e-03
177 3.457031e-01 2.166722e-02 1.084731e-03
178 3.476562e-01 2.256276e-02 1.073017e-03
179 3.496094e-01 2.343047e-02 1.075360e-03
180 3.515625e-01 2.340439e-02 1.101131e-03
181 3.535156e-01 2.301372e-02 1.155016e-03
182 3.554688e-01 2.194478e-02 1.190159e-03
183 3.574219e-01 2.152358e-02 1.190159e-03
184 3.593750e-01 2.131461e-02 1.197187e-03
185 3.613281e-01 2.137841e-02 1.155016e-03
186 3.632812e-01 2.234656e-02 1.133931e-03
187 3.652344e-01 2.309473e-02 1.136274e-03
188 3.671875e-01 2.327779e-02 1.157359e-03
189 3.691406e-01 2.300445e-02 1.143302e-03
190 3.710938e-01 2.296504e-02 1.143302e-03
191 3.730469e-01 2.316280e-02 1.119874e-03
192 3.750000e-01 2.365205e-02 1.091760e-03
193 3.769531e-01 2.425111e-02 1.080046e-03
194 3.789062e-01 2.454003e-02 1.098788e-03
195 3.808594e-01 2.433787e-02 1.131588e-03
196 3.828125e-01 2.364329e-02 1.140959e-03
197 3.847656e-01 2.319790e-02 1.140959e-03
198 3.867188e-01 2.334120e-02 1.103474e-03
199 3.886719e-01 2.383575e-02 1.101131e-03
200 3.906250e-01 2.404536e-02 1.138616e-03
201 3.925781e-01 2.351722e-02 1.129245e-03
202 3.945312e-01 2.331819e-02 1.159702e-03
203 3.964844e-01 2.242555e-02 1.180787e-03
204 3.984375e-01 2.241311e-02 1.180787e-03
205 4.003906e-01 2.226050e-02 1.187816e-03
206 4.023438e-01 2.174728e-02 1.201873e-03
207 4.042969e-01 2.162690e-02 1.199530e-03
208 4.062500e-01 2.164192e-02 1.197187e-03
209 4.082031e-01 2.145375e-02 1.229987e-03
210 4.101562e-01 2.092512e-02 1.244044e-03
211 4.121094e-01 2.049513e-02 1.239358e-03
212 4.140625e-01 2.015864e-02 1.234672e-03
213 4.160156e-01 2.053461e-02 1.192501e-03
214 4.179688e-01 2.143787e-02 1.180787e-03
215 4.199219e-01 2.167968e-02 1.185473e-03
216 4.218750e-01 2.159457e-02 1.194844e-03
217 4.238281e-01 2.152830e-02 1.176102e-03
218 4.257812e-01 2.127001e-02 1.157359e-03
219 4.277344e-01 2.172226e-02 1.115188e-03
220 4.296875e-01 2.253226e-02 1.094103e-03
221 4.316406e-01 2.285307e-02 1.108159e-03
222 4.335938e-01 2.259398e-02 1.096445e-03
223 4.355469e-01 2.250774e-02 1.077703e-03
224 4.375000e-01 2.230789e-02 1.077703e-03
225 4.394531e-01 2.223826e-02 1.070674e-03
226 4.414062e-01 2.240936e-02 1.065988e-03
227 4.433594e-01 2.209735e-02 1.070674e-03
228 4.453125e-01 2.181353e-02 1.089417e-03
229 4.472656e-01 2.125436e-02 1.061303e-03
230 4.492188e-01 2.154117e-02 1.047246e-03
231 4.511719e-01 2.144458e-02 1.075360e-03
232 4.531250e-01 2.102889e-02 1.065988e-03
233 4.550781e-01 2.073943e-02 1.094103e-03
234 4.570312e-01 1.983913e-02 1.115188e-03
235 4.589844e-01 1.924099e-02 1.101131e-03
236 4.609375e-01 1.910224e-02 1.091760e-03
237 4.628906e-01 1.906339e-02 1.080046e-03
238 4.648438e-01 1.914936e-02 1.054274e-03
239 4.667969e-01 1.935795e-02 1.033189e-03
240 4.687500e-01 1.948768e-02 1.042560e-03
241 4.707031e-01 1.918018e-02 1.007418e-03
242 4.726562e-01 1.943166e-02 9.839894e-04
243 4.746094e-01 1.973761e-02 9.558754e-04
244 4.765625e-01 1.996396e-02 9.465041e-04
245 4.785156e-01 2.010844e-02 9.465041e-04
246 4.804688e-01 1.974026e-02 9.793038e-04
247 4.824219e-01 1.852032e-02 9.886752e-04
248 4.843750e-01 1.800370e-02 9.816466e-04
249 4.863281e-01 1.752770e-02 9.535326e-04
250 4.882812e-01 1.807522e-02 9.113617e-04
251 4.902344e-01 1.858815e-02 9.183899e-04
252 4.921875e-01 1.817720e-02 9.113617e-04
253 4.941406e-01 1.788452e-02 9.183899e-04
254 4.960938e-01 1.747828e-02 9.183899e-04
255 4.980469e-01 1.680489e-02 9.113617e-04
256 5.000000e-01 1.680486e-02 9.090189e-04
257 5.019531e-01 1.646112e-02 9.066759e-04
258 5.039062e-01 1.600870e-02 9.230757e-04
259 5.058594e-01 1.522837e-02 9.465041e-04
260 5.078125e-01 1.462920e-02 9.324471e-04
261 5.097656e-01 1.415982e-02 9.160471e-04
262 5.117188e-01 1.396840e-02 8.668476e-04
263 5.136719e-01 1.481614e-02 8.270196e-04
264 5.156250e-01 1.533460e-02 8.106199e-04
265 5.175781e-01 1.537181e-02 8.176482e-04
266 5.195312e-01 1.516842e-02 8.012484e-04
267 5.214844e-01 1.496650e-02 7.942198e-04
268 5.234375e-01 1.453832e-02 7.871916e-04
269 5.253906e-01 1.425156e-02 7.825059e-04
270 5.273438e-01 1.390781e-02 7.614204e-04
271 5.292969e-01 1.351442e-02 7.590775e-04
272 5.312500e-01 1.347387e-02 7.215921e-04
273 5.332031e-01 1.367589e-02 7.098781e-04
274 5.351562e-01 1.343764e-02 7.098781e-04
275 5.371094e-01 1.319271e-02 6.583357e-04
276 5.390625e-01 1.361440e-02 6.278789e-04
277 5.410156e-01 1.358797e-02 6.255360e-04
278 5.429688e-01 1.345999e-02 6.114791e-04
279 5.449219e-01 1.302725e-02 6.231935e-04
280 5.468750e-01 1.232024e-02 6.325645e-04
281 5.488281e-01 1.165887e-02 6.583357e-04
282 5.507812e-01 1.054342e-02 6.466214e-04
283 5.527344e-01 1.004616e-02 6.442789e-04
284 5.546875e-01 9.552332e-03 6.185077e-04
285 5.566406e-01 9.699050e-03 5.880508e-04
286 5.585938e-01 9.797132e-03 5.833652e-04
287 5.605469e-01 9.567765e-03 5.833652e-04
288 5.625000e-01 9.359487e-03 5.739937e-04
289 5.644531e-01 8.628526e-03 5.763365e-04
290 5.664062e-01 8.211902e-03 5.669654e-04
291 5.683594e-01 7.910436e-03 5.435371e-04
292 5.703125e-01 7.801527e-03 5.130802e-04
293 5.722656e-01 7.765540e-03 5.013659e-04
294 5.742188e-01 7.847344e-03 4.943376e-04
295 5.761719e-01 7.417414e-03 5.037087e-04
296 5.781250e-01 6.850646e-03 4.732521e-04
297 5.800781e-01 6.605267e-03 4.217098e-04
298 5.820312e-01 7.044416e-03 3.654818e-04
299 5.839844e-01 7.614722e-03 3.326820e-04
300 5.859375e-01 8.276699e-03 3.092537e-04
301 5.878906e-01 8.293473e-03 3.186252e-04
302 5.898438e-01 7.332624e-03 3.420534e-04
303 5.917969e-01 6.152706e-03 3.350249e-04
304 5.937500e-01 5.730929e-03 2.975397e-04
305 5.957031e-01 5.513668e-03 2.694257e-04
306 5.976562e-01 5.945763e-03 2.342832e-04
307 5.996094e-01 6.047021e-03 2.577115e-04
308 6.015625e-01 4.995086e-03 2.741113e-04
309 6.035156e-01 3.951691e-03 2.881683e-04
310 6.054688e-01 3.160106e-03 2.483402e-04
311 6.074219e-01 2.977545e-03 2.225690e-04
312 6.093750e-01 3.385849e-03 1.827409e-04
313 6.113281e-01 3.437963e-03 1.780552e-04
314 6.132812e-01 3.355744e-03 1.921122e-04
315 6.152344e-01 2.330104e-03 1.944550e-04
316 6.171875e-01 1.476465e-03 2.014836e-04
317 6.191406e-01 5.632552e-04 1.663411e-04
318 6.210938e-01 8.076726e-04 1.007418e-04
319 6.230469e-01 1.718154e-03 4.919947e-05
320 6.250000e-01 2.407283e-03 4.217098e-05
321 6.269531e-01 2.167638e-03 3.982815e-05
322 6.289062e-01 1.625766e-03 3.982815e-05
323 6.308594e-01 8.227843e-04 0.000000e+00
324 6.328125e-01 9.836910e-04 -3.514249e-05
325 6.347656e-01 1.151916e-03 -8.902763e-05
326 6.367188e-01 1.662159e-03 -1.311986e-04
327 6.386719e-01 1.753983e-03 -1.241701e-04
328 6.406250e-01 1.464012e-03 -1.147988e-04
329 6.425781e-01 4.667903e-04 -1.007418e-04
330 6.445312e-01 -6.337452e-04 -8.434193e-05
331 6.464844e-01 -1.532771e-03 -1.147988e-04
332 6.484375e-01 -1.816893e-03 -1.218273e-04
333 6.503906e-01 -2.106634e-03 -1.288557e-04
334 6.523438e-01 -2.340523e-03 -1.452556e-04
335 6.542969e-01 -2.764403e-03 -1.499412e-04
336 6.562500e-01 -3.402951e-03 -1.358842e-04
337 6.582031e-01 -4.194097e-03 -1.194844e-04
338 6.601562e-01 -4.935754e-03 -1.405699e-04
339 6.621094e-01 -5.428637e-03 -1.569697e-04
340 6.640625e-01 -5.476845e-03 -1.850837e-04
341 6.660156e-01 -5.286615e-03 -2.061692e-04
342 6.679688e-01 -5.337538e-03 -1.780552e-04
343 6.699219e-01 -6.230980e-03 -1.874265e-04
344 6.718750e-01 -6.949813e-03 -2.085120e-04
345 6.738281e-01 -7.263456e-03 -2.413117e-04
346 6.757812e-01 -6.889225e-03 -2.998825e-04
347 6.777344e-01 -6.181031e-03 -3.561103e-04
348 6.796875e-01 -5.624621e-03 -3.701675e-04
349 6.816406e-01 -5.605233e-03 -3.842243e-04
350 6.835938e-01 -5.786112e-03 -4.029672e-04
351 6.855469e-01 -6.156884e-03 -4.146812e-04
352 6.875000e-01 -6.384287e-03 -4.334238e-04
353 6.894531e-01 -6.552768e-03 -4.685665e-04
354 6.914062e-01 -6.416261e-03 -4.685665e-04
355 6.933594e-01 -7.095044e-03 -4.896519e-04
356 6.953125e-01 -7.280536e-03 -4.966804e-04
357 6.972656e-01 -7.660145e-03 -5.107374e-04
358 6.992188e-01 -7.973530e-03 -4.779375e-04
359 7.011719e-01 -9.167493e-03 -4.990230e-04
360 7.031250e-01 -9.317879e-03 -5.529082e-04
361 7.050781e-01 -8.832361e-03 -5.833652e-04
362 7.070312e-01 -8.682783e-03 -5.786794e-04
363 7.089844e-01 -9.321115e-03 -5.669654e-04
364 7.109375e-01 -1.018551e-02 -5.271370e-04
365 7.128906e-01 -1.140891e-02 -5.341657e-04
366 7.148438e-01 -1.191754e-02 -5.552511e-04
367 7.167969e-01 -1.224465e-02 -5.693082e-04
368 7.187500e-01 -1.232198e-02 -5.693082e-04
369 7.207031e-01 -1.276342e-02 -5.903937e-04
370 7.226562e-01 -1.291459e-02 -5.927366e-04
371 7.246094e-01 -1.309961e-02 -6.255360e-04
372 7.265625e-01 -1.300269e-02 -6.489643e-04
373 7.285156e-01 -1.278329e-02 -6.677072e-04
374 7.304688e-01 -1.269072e-02 -7.098781e-04
375 7.324219e-01 -1.249247e-02 -7.145638e-04
376 7.343750e-01 -1.289234e-02 -7.333064e-04
377 7.363281e-01 -1.283826e-02 -7.426775e-04
378 7.382812e-01 -1.309437e-02 -7.871916e-04
379 7.402344e-01 -1.276004e-02 -7.989056e-04
380 7.421875e-01 -1.305455e-02 -7.825059e-04
381 7.441406e-01 -1.353827e-02 -7.965628e-04
382 7.460938e-01 -1.396848e-02 -8.504479e-04
383 7.480469e-01 -1.371678e-02 -8.832476e-04
384 7.500000e-01 -1.329405e-02 -9.090189e-04
385 7.519531e-01 -1.303097e-02 -9.183899e-04
386 7.539062e-01 -1.335948e-02 -9.066759e-04
387 7.558594e-01 -1.384436e-02 -8.832476e-04
388 7.578125e-01 -1.483167e-02 -8.902760e-04
389 7.597656e-01 -1.560526e-02 -8.879334e-04
390 7.617188e-01 -1.566686e-02 -9.090189e-04
391 7.636719e-01 -1.580442e-02 -8.996474e-04
392 7.656250e-01 -1.649358e-02 -8.762191e-04
393 7.675781e-01 -1.732299e-02 -8.902760e-04
394 7.695312e-01 -1.767185e-02 -9.113617e-04
395 7.714844e-01 -1.778873e-02 -9.394754e-04
396 7.734375e-01 -1.727366e-02 -9.746180e-04
397 7.753906e-01 -1.670038e-02 -9.957035e-04
398 7.773438e-01 -1.675931e-02 -9.839894e-04
[...]
56 1.093750e-01 -8.511691e+00 -9.691026e+01
57 1.113281e-01 -8.221316e+00 -9.718925e+01
58 1.132812e-01 -7.740133e+00 -9.745377e+01
59 1.152344e-01 -7.448707e+00 -9.770370e+01
60 1.171875e-01 -6.962229e+00 -9.793446e+01
61 1.191406e-01 -6.479935e+00 -9.815552e+01
62 1.210938e-01 -6.182198e+00 -9.836196e+01
63 1.230469e-01 -5.697268e+00 -9.855368e+01
64 1.250000e-01 -5.215804e+00 -9.873074e+01
65 1.269531e-01 -4.922264e+00 -9.889314e+01
66 1.289062e-01 -4.437791e+00 -9.903793e+01
67 1.308594e-01 -3.958343e+00 -9.917107e+01
68 1.328125e-01 -3.661084e+00 -9.934219e+01
69 1.347656e-01 -3.180129e+00 -9.939321e+01
70 1.367188e-01 -2.885154e+00 -9.948219e+01
71 1.386719e-01 -2.403054e+00 -9.955635e+01
72 1.406250e-01 -1.926650e+00 -9.961471e+01
73 1.425781e-01 -1.455679e+00 -9.965966e+01
74 1.445312e-01 -1.163195e+00 -9.968977e+01
75 1.464844e-01 -6.928865e-01 -9.970512e+01
76 1.484375e-01 -4.045157e-01 -9.970581e+01
77 1.503906e-01 6.455109e-02 -9.967957e+01
78 1.523438e-01 5.270391e-01 -9.966380e+01
79 1.542969e-01 9.840969e-01 -9.962080e+01
80 1.562500e-01 1.269678e+00 -9.956316e+01
81 1.582031e-01 1.728451e+00 -9.945039e+01
82 1.601562e-01 2.010474e+00 -9.940430e+01
83 1.621094e-01 2.466077e+00 -9.930546e+01
84 1.640625e-01 2.914320e+00 -9.919012e+01
85 1.660156e-01 3.193010e+00 -9.906026e+01
86 1.679688e-01 3.638092e+00 -9.884026e+01
87 1.699219e-01 4.076538e+00 -9.875761e+01
88 1.718750e-01 4.344744e+00 -9.858482e+01
89 1.738281e-01 4.780084e+00 -9.840161e+01
90 1.757812e-01 5.207764e+00 -9.820035e+01
91 1.777344e-01 5.472507e+00 -9.786945e+01
92 1.796875e-01 5.896460e+00 -9.775513e+01
93 1.816406e-01 6.156283e+00 -9.751107e+01
94 1.835938e-01 6.577067e+00 -9.725281e+01
95 1.855469e-01 6.990485e+00 -9.698596e+01
96 1.875000e-01 7.397112e+00 -9.669944e+01
97 1.894531e-01 7.649041e+00 -9.639868e+01
98 1.914062e-01 7.802790e+00 -9.592416e+01
99 1.933594e-01 8.203577e+00 -9.575436e+01
100 1.953125e-01 8.450312e+00 -9.541083e+01
101 1.972656e-01 8.848340e+00 -9.506055e+01
102 1.992188e-01 9.239668e+00 -9.468896e+01
103 2.011719e-01 9.671751e+00 -9.430318e+01
104 2.031250e-01 9.864789e+00 -9.390318e+01
105 2.050781e-01 1.024661e+01 -9.348900e+01
106 2.070312e-01 1.048324e+01 -9.306059e+01
107 2.089844e-01 1.104874e+01 -9.239615e+01
108 2.109375e-01 1.123463e+01 -9.217087e+01
109 2.128906e-01 1.147041e+01 -9.170046e+01
110 2.148438e-01 1.184062e+01 -9.121592e+01
111 2.167969e-01 1.220469e+01 -9.071732e+01
112 2.187500e-01 1.243464e+01 -9.021524e+01
113 2.207031e-01 1.279644e+01 -8.968886e+01
114 2.226562e-01 1.315303e+01 -8.914857e+01
115 2.246094e-01 1.338332e+01 -8.859440e+01
116 2.265625e-01 1.373781e+01 -8.802631e+01
117 2.285156e-01 1.408563e+01 -8.744434e+01
118 2.304688e-01 1.430857e+01 -8.655173e+01
119 2.324219e-01 1.465141e+01 -8.625163e+01
120 2.343750e-01 1.498893e+01 -8.562875e+01
121 2.363281e-01 1.537976e+01 -8.499236e+01
122 2.382812e-01 1.554613e+01 -8.434239e+01
123 2.402344e-01 1.576729e+01 -8.334924e+01
124 2.421875e-01 1.626452e+01 -8.301627e+01
125 2.441406e-01 1.642838e+01 -8.232663e+01
126 2.460938e-01 1.675133e+01 -8.162389e+01
127 2.480469e-01 1.697064e+01 -8.090813e+01
128 2.500000e-01 1.729207e+01 -8.017943e+01
129 2.519531e-01 1.767197e+01 -7.943784e+01
130 2.539062e-01 1.783187e+01 -7.830965e+01
131 2.558594e-01 1.830225e+01 -7.753680e+01
132 2.578125e-01 1.845738e+01 -7.676775e+01
133 2.597656e-01 1.867538e+01 -7.597057e+01
134 2.617188e-01 1.898301e+01 -7.516124e+01
135 2.636719e-01 1.920191e+01 -7.433993e+01
136 2.656250e-01 1.950843e+01 -7.350670e+01
137 2.675781e-01 1.981012e+01 -7.309435e+01
138 2.695312e-01 2.002962e+01 -7.182292e+01
139 2.714844e-01 2.032746e+01 -7.138163e+01
140 2.734375e-01 2.062006e+01 -7.007628e+01
141 2.753906e-01 2.083583e+01 -6.964174e+01
142 2.773438e-01 2.112571e+01 -6.874638e+01
143 2.792969e-01 2.148407e+01 -6.784018e+01
144 2.812500e-01 2.176782e+01 -6.692335e+01
145 2.832031e-01 2.190745e+01 -6.553802e+01
146 2.851562e-01 2.218373e+01 -6.459540e+01
147 2.871094e-01 2.253268e+01 -6.364276e+01
148 2.890625e-01 2.266880e+01 -6.268022e+01
149 2.910156e-01 2.293606e+01 -6.172800e+01
150 2.929688e-01 2.327844e+01 -6.074651e+01
151 2.949219e-01 2.353897e+01 -5.975560e+01
152 2.968750e-01 2.374756e+01 -5.875554e+01
153 2.988281e-01 2.400246e+01 -5.774652e+01
154 3.007812e-01 2.412838e+01 -5.672874e+01
155 3.027344e-01 2.445651e+01 -5.572338e+01
156 3.046875e-01 2.470286e+01 -5.468878e+01
157 3.066406e-01 2.494578e+01 -5.364584e+01
158 3.085938e-01 2.515166e+01 -5.259480e+01
159 3.105469e-01 2.539226e+01 -5.153594e+01
160 3.125000e-01 2.562857e+01 -5.046937e+01
161 3.144531e-01 2.583454e+01 -4.941722e+01
162 3.164062e-01 2.606780e+01 -4.833593e+01
163 3.183594e-01 2.629787e+01 -4.724734e+01
164 3.203125e-01 2.650306e+01 -4.615180e+01
165 3.222656e-01 2.672904e+01 -4.504943e+01
166 3.242188e-01 2.693580e+01 -4.396309e+01
167 3.261719e-01 2.715834e+01 -4.284773e+01
168 3.281250e-01 2.737831e+01 -4.172601e+01
169 3.300781e-01 2.759428e+01 -4.059814e+01
170 3.320312e-01 2.779960e+01 -3.946427e+01
171 3.339844e-01 2.801202e+01 -3.832464e+01
172 3.359375e-01 2.821802e+01 -3.720283e+01
173 3.378906e-01 2.842632e+01 -3.605223e+01
174 3.398438e-01 2.863242e+01 -3.489629e+01
175 3.417969e-01 2.883600e+01 -3.373525e+01
176 3.437500e-01 2.904293e+01 -3.256933e+01
177 3.457031e-01 2.924474e+01 -3.139872e+01
178 3.476562e-01 2.945749e+01 -3.024761e+01
179 3.496094e-01 2.965993e+01 -2.906817e+01
180 3.515625e-01 2.986071e+01 -2.788448e+01
181 3.535156e-01 3.007784e+01 -2.669672e+01
182 3.554688e-01 3.027881e+01 -2.550507e+01
183 3.574219e-01 3.047751e+01 -2.430975e+01
184 3.593750e-01 3.070128e+01 -2.313542e+01
185 3.613281e-01 3.090185e+01 -2.193331e+01
186 3.632812e-01 3.110032e+01 -2.072802e+01
187 3.652344e-01 3.132706e+01 -1.951971e+01
188 3.671875e-01 3.152272e+01 -1.830859e+01
189 3.691406e-01 3.171767e+01 -1.709482e+01
190 3.710938e-01 3.194725e+01 -1.590346e+01
191 3.730469e-01 3.213715e+01 -1.468499e+01
192 3.750000e-01 3.232387e+01 -1.346436e+01
193 3.769531e-01 3.254773e+01 -1.224183e+01
194 3.789062e-01 3.272630e+01 -1.101746e+01
195 3.808594e-01 3.294823e+01 -9.816490e+00
196 3.828125e-01 3.311555e+01 -8.589059e+00
197 3.847656e-01 3.327740e+01 -7.360258e+00
198 3.867188e-01 3.343315e+01 -6.130308e+00
199 3.886719e-01 3.363668e+01 -4.899389e+00
200 3.906250e-01 3.377843e+01 -3.667670e+00
201 3.925781e-01 3.397457e+01 -2.460445e+00
202 3.945312e-01 3.409932e+01 -1.227604e+00
203 3.964844e-01 3.421547e+01 5.605476e-03
204 3.984375e-01 3.432228e+01 1.238985e+00
205 4.003906e-01 3.448692e+01 2.472148e+00
206 4.023438e-01 3.457353e+01 3.705049e+00
207 4.042969e-01 3.472499e+01 4.912377e+00
208 4.062500e-01 3.478937e+01 6.144166e+00
209 4.082031e-01 3.484275e+01 7.375180e+00
210 4.101562e-01 3.496233e+01 8.605157e+00
211 4.121094e-01 3.499129e+01 9.833893e+00
212 4.140625e-01 3.500933e+01 1.106123e+01
213 4.160156e-01 3.510374e+01 1.226193e+01
214 4.179688e-01 3.509542e+01 1.348577e+01
215 4.199219e-01 3.507451e+01 1.470769e+01
216 4.218750e-01 3.513106e+01 1.592738e+01
217 4.238281e-01 3.508291e+01 1.714471e+01
218 4.257812e-01 3.502314e+01 1.835943e+01
219 4.277344e-01 3.505139e+01 1.954662e+01
220 4.296875e-01 3.496435e+01 2.075552e+01
221 4.316406e-01 3.486567e+01 2.196126e+01
222 4.335938e-01 3.485806e+01 2.316359e+01
223 4.355469e-01 3.473412e+01 2.436239e+01
224 4.375000e-01 3.471001e+01 2.553311e+01
225 4.394531e-01 3.456111e+01 2.672426e+01
226 4.414062e-01 3.440176e+01 2.791128e+01
227 4.433594e-01 3.423273e+01 2.909399e+01
228 4.453125e-01 3.416829e+01 3.027211e+01
229 4.472656e-01 3.397713e+01 3.144560e+01
230 4.492188e-01 3.389945e+01 3.259041e+01
231 4.511719e-01 3.368710e+01 3.375403e+01
232 4.531250e-01 3.346663e+01 3.491246e+01
233 4.550781e-01 3.336106e+01 3.606543e+01
234 4.570312e-01 3.312154e+01 3.721282e+01
235 4.589844e-01 3.287408e+01 3.835442e+01
236 4.609375e-01 3.275211e+01 3.946694e+01
237 4.628906e-01 3.248553e+01 4.059655e+01
238 4.648438e-01 3.221342e+01 4.171992e+01
239 4.667969e-01 3.206944e+01 4.283702e+01
240 4.687500e-01 3.178264e+01 4.394756e+01
241 4.707031e-01 3.163292e+01 4.505134e+01
242 4.726562e-01 3.133241e+01 4.612580e+01
243 4.746094e-01 3.102923e+01 4.721556e+01
244 4.765625e-01 3.072367e+01 4.829799e+01
245 4.785156e-01 3.055844e+01 4.937292e+01
246 4.804688e-01 3.024283e+01 5.044019e+01
247 4.824219e-01 3.007650e+01 5.149965e+01
248 4.843750e-01 2.975229e+01 5.252969e+01
249 4.863281e-01 2.942701e+01 5.357315e+01
250 4.882812e-01 2.910124e+01 5.460826e+01
251 4.902344e-01 2.892564e+01 5.563488e+01
252 4.921875e-01 2.859319e+01 5.665287e+01
253 4.941406e-01 2.841996e+01 5.764159e+01
254 4.960938e-01 2.808161e+01 5.864203e+01
255 4.980469e-01 2.774397e+01 5.963342e+01
256 5.000000e-01 2.740749e+01 6.061554e+01
257 5.019531e-01 2.723023e+01 6.158831e+01
258 5.039062e-01 2.688870e+01 6.255157e+01
259 5.058594e-01 2.671437e+01 6.348582e+01
260 5.078125e-01 2.636778e+01 6.442979e+01
261 5.097656e-01 2.602279e+01 6.536382e+01
262 5.117188e-01 2.584291e+01 6.628773e+01
263 5.136719e-01 2.549318e+01 6.720135e+01
264 5.156250e-01 2.531625e+01 6.810461e+01
265 5.175781e-01 2.496201e+01 6.897921e+01
266 5.195312e-01 2.460937e+01 6.986153e+01
267 5.214844e-01 2.425854e+01 7.073308e+01
268 5.234375e-01 2.407820e+01 7.159371e+01
269 5.253906e-01 2.372157e+01 7.244334e+01
270 5.273438e-01 2.354316e+01 7.328188e+01
271 5.292969e-01 2.318065e+01 7.409237e+01
272 5.312500e-01 2.281952e+01 7.490847e+01
273 5.332031e-01 2.245979e+01 7.571313e+01
274 5.351562e-01 2.227546e+01 7.650615e+01
275 5.371094e-01 2.191007e+01 7.728743e+01
276 5.390625e-01 2.172777e+01 7.805681e+01
277 5.410156e-01 2.135688e+01 7.879895e+01
278 5.429688e-01 2.098715e+01 7.954464e+01
279 5.449219e-01 2.079560e+01 8.027821e+01
280 5.468750e-01 2.041842e+01 8.099957e+01
281 5.488281e-01 2.004293e+01 8.170852e+01
282 5.507812e-01 1.985335e+01 8.239092e+01
283 5.527344e-01 1.947020e+01 8.307516e+01
284 5.546875e-01 1.908875e+01 8.374675e+01
285 5.566406e-01 1.888798e+01 8.440567e+01
286 5.585938e-01 1.849844e+01 8.505164e+01
287 5.605469e-01 1.811011e+01 8.568472e+01
288 5.625000e-01 1.790971e+01 8.629218e+01
289 5.644531e-01 1.751299e+01 8.689938e+01
290 5.664062e-01 1.711695e+01 8.749337e+01
291 5.683594e-01 1.690424e+01 8.807412e+01
292 5.703125e-01 1.649907e+01 8.864146e+01
293 5.722656e-01 1.628303e+01 8.919536e+01
294 5.742188e-01 1.586850e+01 8.972485e+01
295 5.761719e-01 1.545305e+01 9.025188e+01
296 5.781250e-01 1.503772e+01 9.076524e+01
297 5.800781e-01 1.480563e+01 9.126483e+01
298 5.820312e-01 1.437910e+01 9.175048e+01
299 5.839844e-01 1.414146e+01 9.222231e+01
300 5.859375e-01 1.370306e+01 9.267101e+01
301 5.878906e-01 1.326395e+01 9.311514e+01
302 5.898438e-01 1.282366e+01 9.354523e+01
303 5.917969e-01 1.256832e+01 9.396114e+01
304 5.937500e-01 1.211903e+01 9.436279e+01
305 5.957031e-01 1.185895e+01 9.474249e+01
306 5.976562e-01 1.139972e+01 9.511588e+01
307 5.996094e-01 1.094080e+01 9.547498e+01
308 6.015625e-01 1.066637e+01 9.581959e+01
309 6.035156e-01 1.019940e+01 9.614974e+01
310 6.054688e-01 9.733961e+00 9.646535e+01
311 6.074219e-01 9.459212e+00 9.676041e+01
312 6.093750e-01 8.987708e+00 9.704716e+01
313 6.113281e-01 8.517614e+00 9.731938e+01
314 6.132812e-01 8.232265e+00 9.757696e+01
315 6.152344e-01 7.756658e+00 9.781993e+01
316 6.171875e-01 7.284075e+00 9.804830e+01
317 6.191406e-01 7.001404e+00 9.825793e+01
318 6.210938e-01 6.525421e+00 9.845718e+01
319 6.230469e-01 6.053534e+00 9.864182e+01
320 6.250000e-01 5.764588e+00 9.881168e+01
321 6.269531e-01 5.289428e+00 9.896691e+01
322 6.289062e-01 5.001390e+00 9.910732e+01
323 6.308594e-01 4.523422e+00 9.923063e+01
324 6.328125e-01 4.050476e+00 9.934180e+01
325 6.347656e-01 3.582590e+00 9.943819e+01
326 6.367188e-01 3.295115e+00 9.951979e+01
327 6.386719e-01 2.825530e+00 9.958666e+01
328 6.406250e-01 2.540057e+00 9.963779e+01
329 6.425781e-01 2.069152e+00 9.967538e+01
330 6.445312e-01 1.603601e+00 9.969820e+01
331 6.464844e-01 1.143281e+00 9.970624e+01
332 6.484375e-01 8.587704e-01 9.969958e+01
333 6.503906e-01 3.976624e-01 9.967834e+01
334 6.523438e-01 1.159755e-01 9.964323e+01
335 6.542969e-01 -3.450373e-01 9.959296e+01
336 6.562500e-01 -8.011118e-01 9.952821e+01
337 6.582031e-01 -1.087617e+00 9.944889e+01
338 6.601562e-01 -1.547641e+00 9.935518e+01
339 6.621094e-01 -2.002311e+00 9.924686e+01
340 6.640625e-01 -2.283215e+00 9.912687e+01
341 6.660156e-01 -2.736950e+00 9.899000e+01
342 6.679688e-01 -3.184626e+00 9.883885e+01
343 6.699219e-01 -3.465938e+00 9.867346e+01
344 6.718750e-01 -3.911930e+00 9.849371e+01
345 6.738281e-01 -4.351541e+00 9.829964e+01
346 6.757812e-01 -4.624150e+00 9.809569e+01
347 6.777344e-01 -5.061970e+00 9.787338e+01
348 6.796875e-01 -5.493169e+00 9.763688e+01
349 6.816406e-01 -5.764814e+00 9.738620e+01
350 6.835938e-01 -6.193666e+00 9.712124e+01
351 6.855469e-01 -6.461657e+00 9.684786e+01
352 6.875000e-01 -6.887734e+00 9.655472e+01
353 6.894531e-01 -7.307405e+00 9.624729e+01
354 6.914062e-01 -7.720564e+00 9.592580e+01
355 6.933594e-01 -7.982813e+00 9.559008e+01
356 6.953125e-01 -8.393928e+00 9.524017e+01
357 6.972656e-01 -8.653482e+00 9.488365e+01
358 6.992188e-01 -9.062311e+00 9.450566e+01
359 7.011719e-01 -9.464531e+00 9.411358e+01
360 7.031250e-01 -9.859927e+00 9.370728e+01
361 7.050781e-01 -1.011259e+01 9.328690e+01
362 7.070312e-01 -1.050475e+01 9.285229e+01
363 7.089844e-01 -1.075415e+01 9.241286e+01
364 7.109375e-01 -1.114308e+01 9.195029e+01
365 7.128906e-01 -1.152544e+01 9.147377e+01
366 7.148438e-01 -1.177353e+01 9.098309e+01
367 7.167969e-01 -1.215300e+01 9.047839e+01
368 7.187500e-01 -1.252648e+01 8.995964e+01
369 7.207031e-01 -1.276771e+01 8.943794e+01
370 7.226562e-01 -1.313838e+01 8.889160e+01
371 7.246094e-01 -1.350360e+01 8.833140e+01
372 7.265625e-01 -1.374428e+01 8.775731e+01
373 7.285156e-01 -1.410579e+01 8.716936e+01
374 7.304688e-01 -1.446085e+01 8.656767e+01
375 7.324219e-01 -1.469510e+01 8.596494e+01
376 7.343750e-01 -1.504788e+01 8.533627e+01
377 7.363281e-01 -1.539527e+01 8.469408e+01
378 7.382812e-01 -1.563017e+01 8.403848e+01
379 7.402344e-01 -1.597525e+01 8.336942e+01
380 7.421875e-01 -1.620834e+01 8.270108e+01
381 7.441406e-01 -1.655043e+01 8.200574e+01
382 7.460938e-01 -1.688703e+01 8.129734e+01
383 7.480469e-01 -1.721862e+01 8.057590e+01
384 7.500000e-01 -1.744795e+01 7.984157e+01
385 7.519531e-01 -1.777583e+01 7.909441e+01
386 7.539062e-01 -1.800343e+01 7.835022e+01
387 7.558594e-01 -1.832800e+01 7.757811e+01
388 7.578125e-01 -1.864707e+01 7.679359e+01
389 7.597656e-01 -1.896093e+01 7.599678e+01
390 7.617188e-01 -1.918458e+01 7.518781e+01
391 7.636719e-01 -1.949459e+01 7.436685e+01
392 7.656250e-01 -1.971737e+01 7.355115e+01
393 7.675781e-01 -2.002358e+01 7.270689e+01
394 7.695312e-01 -2.032403e+01 7.185108e+01
395 7.714844e-01 -2.054413e+01 7.098379e+01
396 7.734375e-01 -2.083902e+01 7.010525e+01
397 7.753906e-01 -2.112870e+01 6.921564e+01
398 7.773438e-01 -2.134417e+01 6.833369e+01
399 7.792969e-01 -2.163036e+01 6.742277e+01
400 7.812500e-01 -2.191112e+01 6.650128e+01
401 7.832031e-01 -2.212427e+01 6.556945e+01
402 7.851562e-01 -2.239957e+01 6.462733e+01
403 7.871094e-01 -2.261128e+01 6.367521e+01
404 7.890625e-01 -2.288191e+01 6.273297e+01
405 7.910156e-01 -2.314731e+01 6.176152e+01
406 7.929688e-01 -2.340745e+01 6.078061e+01
407 7.949219e-01 -2.361300e+01 5.979030e+01
408 7.968750e-01 -2.386759e+01 5.879078e+01
409 7.988281e-01 -2.407139e+01 5.780290e+01
410 8.007812e-01 -2.432030e+01 5.678572e+01
411 8.027344e-01 -2.456491e+01 5.575991e+01
412 8.046875e-01 -2.476658e+01 5.472564e+01
413 8.066406e-01 -2.500795e+01 5.368303e+01
414 8.085938e-01 -2.524545e+01 5.263229e+01
415 8.105469e-01 -2.544883e+01 5.159526e+01
416 8.125000e-01 -2.568281e+01 5.052893e+01
417 8.144531e-01 -2.591395e+01 4.945498e+01
418 8.164062e-01 -2.611481e+01 4.837362e+01
419 8.183594e-01 -2.634307e+01 4.728504e+01
420 8.203125e-01 -2.656682e+01 4.618935e+01
421 8.222656e-01 -2.677029e+01 4.510937e+01
422 8.242188e-01 -2.699065e+01 4.400025e+01
423 8.261719e-01 -2.720831e+01 4.288456e+01
424 8.281250e-01 -2.740896e+01 4.176247e+01
425 8.300781e-01 -2.762312e+01 4.063416e+01
426 8.320312e-01 -2.782725e+01 3.949977e+01
427 8.339844e-01 -2.803697e+01 3.838285e+01
428 8.359375e-01 -2.824431e+01 3.723705e+01
429 8.378906e-01 -2.844790e+01 3.608576e+01
430 8.398438e-01 -2.865059e+01 3.492913e+01
431 8.417969e-01 -2.885456e+01 3.376728e+01
432 8.437500e-01 -2.906060e+01 3.260046e+01
433 8.457031e-01 -2.926272e+01 3.145282e+01
434 8.476562e-01 -2.946337e+01 3.027673e+01
435 8.496094e-01 -2.967561e+01 2.909615e+01
436 8.515625e-01 -2.987766e+01 2.791125e+01
437 8.535156e-01 -3.007814e+01 2.672219e+01
438 8.554688e-01 -3.029823e+01 2.555356e+01
439 8.574219e-01 -3.049825e+01 2.435681e+01
440 8.593750e-01 -3.069893e+01 2.315647e+01
441 8.613281e-01 -3.092451e+01 2.195275e+01
442 8.632812e-01 -3.112513e+01 2.074572e+01
443 8.652344e-01 -3.132496e+01 1.953568e+01
444 8.671875e-01 -3.155590e+01 1.834747e+01
445 8.691406e-01 -3.175269e+01 1.713187e+01
446 8.710938e-01 -3.194850e+01 1.591373e+01
447 8.730469e-01 -3.217985e+01 1.469326e+01
448 8.750000e-01 -3.237030e+01 1.347057e+01
449 8.769531e-01 -3.260120e+01 1.224586e+01
450 8.789062e-01 -3.278337e+01 1.104446e+01
451 8.808594e-01 -3.296104e+01 9.816332e+00
452 8.828125e-01 -3.313483e+01 8.586750e+00
453 8.847656e-01 -3.335353e+01 7.355816e+00
454 8.867188e-01 -3.351562e+01 6.123710e+00
455 8.886719e-01 -3.372813e+01 4.890596e+00
456 8.906250e-01 -3.387572e+01 3.681879e+00
457 8.925781e-01 -3.401648e+01 2.447327e+00
458 8.945312e-01 -3.414921e+01 1.212305e+00
459 8.964844e-01 -3.433660e+01 -2.295784e-02
460 8.984375e-01 -3.445011e+01 -1.258348e+00
461 9.003906e-01 -3.462426e+01 -2.493664e+00
462 9.023438e-01 -3.471692e+01 -3.703402e+00
463 9.042969e-01 -3.480040e+01 -4.937946e+00
464 9.062500e-01 -3.494637e+01 -6.171747e+00
465 9.082031e-01 -3.500630e+01 -7.404672e+00
466 9.101562e-01 -3.505454e+01 -8.636607e+00
467 9.121094e-01 -3.517421e+01 -9.842137e+00
468 9.140625e-01 -3.519743e+01 -1.107135e+01
469 9.160156e-01 -3.520932e+01 -1.229897e+01
470 9.179688e-01 -3.529485e+01 -1.352478e+01
471 9.199219e-01 -3.527945e+01 -1.474854e+01
472 9.218750e-01 -3.525112e+01 -1.597009e+01
473 9.238281e-01 -3.530628e+01 -1.716441e+01
474 9.257812e-01 -3.525116e+01 -1.838101e+01
475 9.277344e-01 -3.518485e+01 -1.959478e+01
476 9.296875e-01 -3.520502e+01 -2.080552e+01
477 9.316406e-01 -3.511120e+01 -2.201306e+01
478 9.335938e-01 -3.511126e+01 -2.321729e+01
479 9.355469e-01 -3.499038e+01 -2.439345e+01
480 9.375000e-01 -3.485862e+01 -2.559040e+01
481 9.394531e-01 -3.471638e+01 -2.678335e+01
482 9.414062e-01 -3.467267e+01 -2.797212e+01
483 9.433594e-01 -3.450470e+01 -2.915660e+01
484 9.453125e-01 -3.444425e+01 -3.031248e+01
485 9.472656e-01 -3.425208e+01 -3.148782e+01
486 9.492188e-01 -3.405138e+01 -3.265825e+01
487 9.511719e-01 -3.384185e+01 -3.382357e+01
488 9.531250e-01 -3.374471e+01 -3.498362e+01
489 9.550781e-01 -3.351402e+01 -3.613815e+01
490 9.570312e-01 -3.340522e+01 -3.726365e+01
491 9.589844e-01 -3.315554e+01 -3.840675e+01
492 9.609375e-01 -3.289985e+01 -3.954389e+01
493 9.628906e-01 -3.276699e+01 -4.067485e+01
494 9.648438e-01 -3.249360e+01 -4.179960e+01
495 9.667969e-01 -3.221554e+01 -4.291784e+01
496 9.687500e-01 -3.207300e+01 -4.400673e+01
497 9.707031e-01 -3.178212e+01 -4.511138e+01
498 9.726562e-01 -3.148847e+01 -4.620893e+01
499 9.746094e-01 -3.133129e+01 -4.729922e+01
500 9.765625e-01 -3.102582e+01 -4.838208e+01
501 9.785156e-01 -3.071832e+01 -4.945741e+01
502 9.804688e-01 -3.055830e+01 -5.050320e+01
503 9.824219e-01 -3.024157e+01 -5.156293e+01
504 9.843750e-01 -2.992436e+01 -5.261454e+01
505 9.863281e-01 -2.975398e+01 -5.365786e+01
506 9.882812e-01 -2.942748e+01 -5.469279e+01
507 9.902344e-01 -2.925606e+01 -5.569828e+01
508 9.921875e-01 -2.892134e+01 -5.671612e+01
509 9.941406e-01 -2.858754e+01 -5.772505e+01
510 9.960938e-01 -2.825425e+01 -5.872498e+01
511 9.980469e-01 -2.807681e+01 -5.971571e+01