File: samples/4h2%_mini/2%.txt
Datapoint no.: 0
 #  Time [s]  Stress [Pa]  Strain [-]
TorqueRatio 8.954097e-01
AngleRatio 1.176536e+00
0 0.000000e+00 7.361796e-04 -1.381560e-01
1 1.953125e-03 7.441178e-04 -1.381567e-01
2 3.906250e-03 7.519437e-04 -1.381573e-01
3 5.859375e-03 7.596564e-04 -1.381579e-01
4 7.812500e-03 7.630390e-04 -1.381585e-01
5 9.765625e-03 7.704805e-04 -1.381591e-01
6 1.171875e-02 7.778062e-04 -1.381599e-01
7 1.367188e-02 7.850147e-04 -1.381606e-01
8 1.562500e-02 7.921051e-04 -1.381615e-01
9 1.757812e-02 7.990760e-04 -1.381626e-01
10 1.953125e-02 8.059266e-04 -1.381637e-01
11 2.148438e-02 8.126560e-04 -1.381650e-01
12 2.343750e-02 8.192629e-04 -1.381665e-01
13 2.539062e-02 8.257463e-04 -1.381682e-01
14 2.734375e-02 8.321055e-04 -1.381699e-01
15 2.929688e-02 8.383394e-04 -1.381718e-01
16 3.125000e-02 8.444469e-04 -1.381738e-01
17 3.320312e-02 8.504272e-04 -1.381759e-01
18 3.515625e-02 8.562797e-04 -1.381781e-01
19 3.710938e-02 8.620030e-04 -1.381803e-01
20 3.906250e-02 8.675967e-04 -1.381825e-01
21 4.101562e-02 8.730597e-04 -1.381847e-01
22 4.296875e-02 8.783911e-04 -1.381868e-01
23 4.492188e-02 8.835902e-04 -1.381888e-01
24 4.687500e-02 8.886564e-04 -1.381907e-01
25 4.882812e-02 8.935885e-04 -1.381924e-01
26 5.078125e-02 8.983863e-04 -1.381941e-01
27 5.273438e-02 9.030488e-04 -1.381955e-01
28 5.468750e-02 9.075752e-04 -1.381967e-01
29 5.664062e-02 9.119649e-04 -1.381978e-01
30 5.859375e-02 9.162172e-04 -1.381987e-01
31 6.054688e-02 9.203317e-04 -1.381995e-01
32 6.250000e-02 9.243074e-04 -1.382001e-01
33 6.445312e-02 9.281443e-04 -1.382006e-01
34 6.640625e-02 9.318410e-04 -1.382010e-01
35 6.835938e-02 9.353975e-04 -1.382014e-01
36 7.031250e-02 9.388132e-04 -1.382017e-01
37 7.226562e-02 9.420876e-04 -1.382020e-01
38 7.421875e-02 9.452198e-04 -1.382024e-01
39 7.617188e-02 9.482099e-04 -1.382027e-01
40 7.812500e-02 9.510571e-04 -1.382032e-01
41 8.007812e-02 9.537612e-04 -1.382038e-01
42 8.203125e-02 9.563216e-04 -1.382045e-01
43 8.398438e-02 9.587379e-04 -1.382053e-01
44 8.593750e-02 9.610099e-04 -1.382063e-01
45 8.789062e-02 9.631371e-04 -1.382074e-01
46 8.984375e-02 9.651195e-04 -1.382087e-01
47 9.179688e-02 9.669564e-04 -1.382101e-01
48 9.375000e-02 9.686475e-04 -1.382117e-01
49 9.570312e-02 9.701928e-04 -1.382134e-01
50 9.765625e-02 9.715921e-04 -1.382152e-01
51 9.960938e-02 9.728452e-04 -1.382170e-01
52 1.015625e-01 9.739516e-04 -1.382190e-01
53 1.035156e-01 9.749114e-04 -1.382209e-01
54 1.054688e-01 9.757243e-04 -1.382229e-01
55 1.074219e-01 9.763904e-04 -1.382248e-01
56 1.093750e-01 9.769092e-04 -1.382267e-01
57 1.113281e-01 9.772811e-04 -1.382286e-01
58 1.132812e-01 9.775058e-04 -1.382303e-01
59 1.152344e-01 9.775833e-04 -1.382320e-01
60 1.171875e-01 9.775136e-04 -1.382335e-01
61 1.191406e-01 9.772966e-04 -1.382350e-01
62 1.210938e-01 9.769324e-04 -1.382363e-01
63 1.230469e-01 9.764213e-04 -1.382376e-01
64 1.250000e-01 9.757629e-04 -1.382387e-01
65 1.269531e-01 9.749577e-04 -1.382397e-01
66 1.289062e-01 9.740056e-04 -1.382406e-01
67 1.308594e-01 9.729068e-04 -1.382414e-01
68 1.328125e-01 9.716616e-04 -1.382422e-01
69 1.347656e-01 9.702700e-04 -1.382430e-01
70 1.367188e-01 9.687322e-04 -1.382437e-01
71 1.386719e-01 9.670486e-04 -1.382445e-01
72 1.406250e-01 9.652196e-04 -1.382453e-01
73 1.425781e-01 9.632448e-04 -1.382461e-01
74 1.445312e-01 9.611251e-04 -1.382471e-01
75 1.464844e-01 9.588607e-04 -1.382480e-01
76 1.484375e-01 9.564519e-04 -1.382491e-01
77 1.503906e-01 9.538992e-04 -1.382503e-01
78 1.523438e-01 9.512028e-04 -1.382515e-01
79 1.542969e-01 9.483630e-04 -1.382529e-01
80 1.562500e-01 9.453804e-04 -1.382544e-01
81 1.582031e-01 9.422554e-04 -1.382559e-01
82 1.601562e-01 9.389887e-04 -1.382576e-01
83 1.621094e-01 9.355802e-04 -1.382593e-01
84 1.640625e-01 9.320313e-04 -1.382610e-01
85 1.660156e-01 9.283418e-04 -1.382629e-01
86 1.679688e-01 9.245124e-04 -1.382646e-01
87 1.699219e-01 9.205439e-04 -1.382665e-01
88 1.718750e-01 9.164367e-04 -1.382682e-01
89 1.738281e-01 9.121915e-04 -1.382700e-01
90 1.757812e-01 9.078089e-04 -1.382717e-01
91 1.777344e-01 9.032898e-04 -1.382733e-01
92 1.796875e-01 8.986345e-04 -1.382747e-01
93 1.816406e-01 8.938438e-04 -1.382761e-01
94 1.835938e-01 8.889186e-04 -1.382774e-01
95 1.855469e-01 8.838596e-04 -1.382785e-01
96 1.875000e-01 8.786673e-04 -1.382795e-01
97 1.894531e-01 8.733428e-04 -1.382804e-01
98 1.914062e-01 8.678868e-04 -1.382812e-01
99 1.933594e-01 8.622999e-04 -1.382818e-01
100 1.953125e-01 8.565833e-04 -1.382824e-01
101 1.972656e-01 8.507377e-04 -1.382829e-01
102 1.992188e-01 8.447641e-04 -1.382834e-01
103 2.011719e-01 8.386631e-04 -1.382838e-01
104 2.031250e-01 8.324360e-04 -1.382843e-01
105 2.050781e-01 8.260832e-04 -1.382848e-01
106 2.070312e-01 8.196062e-04 -1.382854e-01
107 2.089844e-01 8.130058e-04 -1.382861e-01
108 2.109375e-01 8.062830e-04 -1.382869e-01
109 2.128906e-01 7.994387e-04 -1.382879e-01
110 2.148438e-01 7.924744e-04 -1.382890e-01
111 2.167969e-01 7.853904e-04 -1.382903e-01
112 2.187500e-01 7.781888e-04 -1.382918e-01
113 2.207031e-01 7.708700e-04 -1.382935e-01
114 2.226562e-01 7.634354e-04 -1.382953e-01
115 2.246094e-01 7.558863e-04 -1.382973e-01
116 2.265625e-01 7.482237e-04 -1.382994e-01
117 2.285156e-01 7.404490e-04 -1.383017e-01
118 2.304688e-01 7.325636e-04 -1.383040e-01
119 2.324219e-01 7.245685e-04 -1.383064e-01
120 2.343750e-01 7.164648e-04 -1.383087e-01
121 2.363281e-01 7.082543e-04 -1.383111e-01
122 2.382812e-01 6.999378e-04 -1.383134e-01
123 2.402344e-01 6.915170e-04 -1.383156e-01
124 2.421875e-01 6.829930e-04 -1.383177e-01
125 2.441406e-01 6.743669e-04 -1.383196e-01
126 2.460938e-01 6.656402e-04 -1.383214e-01
127 2.480469e-01 6.568143e-04 -1.383229e-01
128 2.500000e-01 6.478903e-04 -1.383243e-01
129 2.519531e-01 6.388698e-04 -1.383254e-01
130 2.539062e-01 6.297538e-04 -1.383263e-01
131 2.558594e-01 6.205437e-04 -1.383270e-01
132 2.578125e-01 6.112409e-04 -1.383276e-01
133 2.597656e-01 6.018467e-04 -1.383280e-01
134 2.617188e-01 5.923624e-04 -1.383283e-01
135 2.636719e-01 5.827894e-04 -1.383285e-01
136 2.656250e-01 5.731288e-04 -1.383287e-01
137 2.675781e-01 5.633823e-04 -1.383288e-01
138 2.695312e-01 5.535508e-04 -1.383290e-01
139 2.714844e-01 5.436363e-04 -1.383292e-01
140 2.734375e-01 5.336397e-04 -1.383295e-01
141 2.753906e-01 5.235625e-04 -1.383300e-01
142 2.773438e-01 5.134062e-04 -1.383306e-01
143 2.792969e-01 5.031722e-04 -1.383313e-01
144 2.812500e-01 4.928617e-04 -1.383323e-01
145 2.832031e-01 4.824764e-04 -1.383334e-01
146 2.851562e-01 4.720177e-04 -1.383347e-01
147 2.871094e-01 4.614870e-04 -1.383362e-01
148 2.890625e-01 4.508860e-04 -1.383378e-01
149 2.910156e-01 4.402160e-04 -1.383395e-01
150 2.929688e-01 4.294786e-04 -1.383414e-01
151 2.949219e-01 4.186751e-04 -1.383434e-01
152 2.968750e-01 4.078076e-04 -1.383454e-01
153 2.988281e-01 3.968770e-04 -1.383474e-01
154 3.007812e-01 3.858854e-04 -1.383494e-01
155 3.027344e-01 3.748343e-04 -1.383514e-01
156 3.046875e-01 3.637251e-04 -1.383534e-01
157 3.066406e-01 3.525597e-04 -1.383552e-01
158 3.085938e-01 3.413396e-04 -1.383570e-01
159 3.105469e-01 3.300664e-04 -1.383586e-01
160 3.125000e-01 3.187418e-04 -1.383602e-01
161 3.144531e-01 3.073676e-04 -1.383616e-01
162 3.164062e-01 2.959454e-04 -1.383628e-01
163 3.183594e-01 2.844769e-04 -1.383640e-01
164 3.203125e-01 2.729640e-04 -1.383652e-01
165 3.222656e-01 2.614082e-04 -1.383662e-01
166 3.242188e-01 2.498112e-04 -1.383672e-01
167 3.261719e-01 2.381750e-04 -1.383682e-01
168 3.281250e-01 2.265015e-04 -1.383692e-01
169 3.300781e-01 2.147920e-04 -1.383702e-01
170 3.320312e-01 2.030486e-04 -1.383713e-01
171 3.339844e-01 1.912730e-04 -1.383725e-01
172 3.359375e-01 1.794669e-04 -1.383737e-01
173 3.378906e-01 1.676323e-04 -1.383751e-01
174 3.398438e-01 1.557709e-04 -1.383766e-01
175 3.417969e-01 1.438846e-04 -1.383782e-01
176 3.437500e-01 1.319752e-04 -1.383799e-01
177 3.457031e-01 1.200444e-04 -1.383817e-01
178 3.476562e-01 1.080941e-04 -1.383836e-01
179 3.496094e-01 9.612623e-05 -1.383857e-01
180 3.515625e-01 8.414256e-05 -1.383877e-01
181 3.535156e-01 7.214492e-05 -1.383898e-01
182 3.554688e-01 6.013518e-05 -1.383919e-01
183 3.574219e-01 4.811516e-05 -1.383939e-01
184 3.593750e-01 3.608673e-05 -1.383960e-01
185 3.613281e-01 2.405174e-05 -1.383979e-01
186 3.632812e-01 1.201202e-05 -1.383998e-01
187 3.652344e-01 -3.054397e-08 -1.384016e-01
188 3.671875e-01 -1.207412e-05 -1.384033e-01
189 3.691406e-01 -2.411685e-05 -1.384048e-01
190 3.710938e-01 -3.615689e-05 -1.384063e-01
191 3.730469e-01 -4.819241e-05 -1.384076e-01
192 3.750000e-01 -6.022151e-05 -1.384088e-01
193 3.769531e-01 -7.224237e-05 -1.384099e-01
194 3.789062e-01 -8.425317e-05 -1.384109e-01
195 3.808594e-01 -9.625204e-05 -1.384119e-01
196 3.828125e-01 -1.082371e-04 -1.384128e-01
197 3.847656e-01 -1.202066e-04 -1.384137e-01
198 3.867188e-01 -1.321587e-04 -1.384146e-01
199 3.886719e-01 -1.440915e-04 -1.384155e-01
200 3.906250e-01 -1.560032e-04 -1.384165e-01
201 3.925781e-01 -1.678920e-04 -1.384174e-01
202 3.945312e-01 -1.797560e-04 -1.384185e-01
203 3.964844e-01 -1.915935e-04 -1.384197e-01
204 3.984375e-01 -2.034027e-04 -1.384209e-01
205 4.003906e-01 -2.151817e-04 -1.384222e-01
206 4.023438e-01 -2.269288e-04 -1.384236e-01
207 4.042969e-01 -2.386421e-04 -1.384251e-01
208 4.062500e-01 -2.503199e-04 -1.384267e-01
209 4.082031e-01 -2.619603e-04 -1.384283e-01
210 4.101562e-01 -2.735617e-04 -1.384299e-01
211 4.121094e-01 -2.851221e-04 -1.384315e-01
212 4.140625e-01 -2.966401e-04 -1.384333e-01
213 4.160156e-01 -3.081137e-04 -1.384349e-01
214 4.179688e-01 -3.195411e-04 -1.384366e-01
215 4.199219e-01 -3.309208e-04 -1.384382e-01
216 4.218750e-01 -3.422507e-04 -1.384398e-01
217 4.238281e-01 -3.535294e-04 -1.384413e-01
218 4.257812e-01 -3.647552e-04 -1.384427e-01
219 4.277344e-01 -3.759263e-04 -1.384441e-01
220 4.296875e-01 -3.870410e-04 -1.384455e-01
221 4.316406e-01 -3.980974e-04 -1.384467e-01
222 4.335938e-01 -4.090941e-04 -1.384480e-01
223 4.355469e-01 -4.200295e-04 -1.384491e-01
224 4.375000e-01 -4.309017e-04 -1.384503e-01
225 4.394531e-01 -4.417094e-04 -1.384514e-01
226 4.414062e-01 -4.524503e-04 -1.384525e-01
227 4.433594e-01 -4.631236e-04 -1.384536e-01
228 4.453125e-01 -4.737271e-04 -1.384548e-01
229 4.472656e-01 -4.842593e-04 -1.384560e-01
230 4.492188e-01 -4.947188e-04 -1.384572e-01
231 4.511719e-01 -5.051038e-04 -1.384585e-01
232 4.531250e-01 -5.154131e-04 -1.384599e-01
233 4.550781e-01 -5.256446e-04 -1.384614e-01
234 4.570312e-01 -5.357972e-04 -1.384631e-01
235 4.589844e-01 -5.458691e-04 -1.384647e-01
236 4.609375e-01 -5.558588e-04 -1.384665e-01
237 4.628906e-01 -5.657650e-04 -1.384683e-01
238 4.648438e-01 -5.755860e-04 -1.384703e-01
239 4.667969e-01 -5.853203e-04 -1.384723e-01
240 4.687500e-01 -5.949668e-04 -1.384744e-01
241 4.707031e-01 -6.045235e-04 -1.384766e-01
242 4.726562e-01 -6.139892e-04 -1.384787e-01
243 4.746094e-01 -6.233627e-04 -1.384809e-01
244 4.765625e-01 -6.326421e-04 -1.384831e-01
245 4.785156e-01 -6.418264e-04 -1.384853e-01
246 4.804688e-01 -6.509142e-04 -1.384874e-01
247 4.824219e-01 -6.599038e-04 -1.384894e-01
248 4.843750e-01 -6.687942e-04 -1.384914e-01
249 4.863281e-01 -6.775839e-04 -1.384933e-01
250 4.882812e-01 -6.862716e-04 -1.384952e-01
251 4.902344e-01 -6.948560e-04 -1.384969e-01
252 4.921875e-01 -7.033357e-04 -1.384984e-01
253 4.941406e-01 -7.117094e-04 -1.385000e-01
254 4.960938e-01 -7.199760e-04 -1.385013e-01
255 4.980469e-01 -7.281344e-04 -1.385026e-01
256 5.000000e-01 -7.361830e-04 -1.385037e-01
257 5.019531e-01 -7.441207e-04 -1.385047e-01
258 5.039062e-01 -7.519465e-04 -1.385057e-01
259 5.058594e-01 -7.596589e-04 -1.385065e-01
260 5.078125e-01 -7.672571e-04 -1.385072e-01
261 5.097656e-01 -7.747398e-04 -1.385079e-01
262 5.117188e-01 -7.821058e-04 -1.385086e-01
263 5.136719e-01 -7.893540e-04 -1.385092e-01
264 5.156250e-01 -7.964832e-04 -1.385098e-01
265 5.175781e-01 -8.034926e-04 -1.385104e-01
266 5.195312e-01 -8.103810e-04 -1.385109e-01
267 5.214844e-01 -8.171473e-04 -1.385116e-01
268 5.234375e-01 -8.237906e-04 -1.385123e-01
269 5.253906e-01 -8.303098e-04 -1.385130e-01
270 5.273438e-01 -8.367041e-04 -1.385138e-01
271 5.292969e-01 -8.429721e-04 -1.385146e-01
272 5.312500e-01 -8.491135e-04 -1.385155e-01
273 5.332031e-01 -8.551269e-04 -1.385166e-01
274 5.351562e-01 -8.610115e-04 -1.385176e-01
275 5.371094e-01 -8.667665e-04 -1.385188e-01
276 5.390625e-01 -8.723908e-04 -1.385200e-01
277 5.410156e-01 -8.778840e-04 -1.385212e-01
278 5.429688e-01 -8.832447e-04 -1.385225e-01
279 5.449219e-01 -8.884727e-04 -1.385238e-01
280 5.468750e-01 -8.935666e-04 -1.385252e-01
281 5.488281e-01 -8.985262e-04 -1.385265e-01
282 5.507812e-01 -9.033504e-04 -1.385279e-01
283 5.527344e-01 -9.080384e-04 -1.385291e-01
284 5.546875e-01 -9.125900e-04 -1.385304e-01
285 5.566406e-01 -9.170040e-04 -1.385316e-01
286 5.585938e-01 -9.212797e-04 -1.385327e-01
287 5.605469e-01 -9.254168e-04 -1.385338e-01
288 5.625000e-01 -9.294146e-04 -1.385349e-01
289 5.644531e-01 -9.332725e-04 -1.385359e-01
290 5.664062e-01 -9.369896e-04 -1.385368e-01
291 5.683594e-01 -9.405658e-04 -1.385378e-01
292 5.703125e-01 -9.440003e-04 -1.385388e-01
293 5.722656e-01 -9.472927e-04 -1.385398e-01
294 5.742188e-01 -9.504425e-04 -1.385408e-01
295 5.761719e-01 -9.534489e-04 -1.385419e-01
296 5.781250e-01 -9.563119e-04 -1.385431e-01
297 5.800781e-01 -9.590309e-04 -1.385443e-01
298 5.820312e-01 -9.616053e-04 -1.385458e-01
299 5.839844e-01 -9.640350e-04 -1.385473e-01
300 5.859375e-01 -9.663196e-04 -1.385490e-01
301 5.878906e-01 -9.684586e-04 -1.385508e-01
302 5.898438e-01 -9.704517e-04 -1.385527e-01
303 5.917969e-01 -9.722988e-04 -1.385547e-01
304 5.937500e-01 -9.739993e-04 -1.385569e-01
305 5.957031e-01 -9.755532e-04 -1.385592e-01
306 5.976562e-01 -9.769603e-04 -1.385615e-01
307 5.996094e-01 -9.782201e-04 -1.385638e-01
308 6.015625e-01 -9.793328e-04 -1.385662e-01
309 6.035156e-01 -9.802979e-04 -1.385684e-01
310 6.054688e-01 -9.811153e-04 -1.385705e-01
311 6.074219e-01 -9.817850e-04 -1.385726e-01
312 6.093750e-01 -9.823067e-04 -1.385745e-01
313 6.113281e-01 -9.826806e-04 -1.385762e-01
314 6.132812e-01 -9.829066e-04 -1.385777e-01
315 6.152344e-01 -9.829844e-04 -1.385790e-01
316 6.171875e-01 -9.829144e-04 -1.385799e-01
317 6.191406e-01 -9.826962e-04 -1.385807e-01
318 6.210938e-01 -9.823301e-04 -1.385812e-01
319 6.230469e-01 -9.818160e-04 -1.385814e-01
320 6.250000e-01 -9.811540e-04 -1.385814e-01
321 6.269531e-01 -9.803444e-04 -1.385812e-01
322 6.289062e-01 -9.793871e-04 -1.385808e-01
323 6.308594e-01 -9.782822e-04 -1.385802e-01
324 6.328125e-01 -9.770300e-04 -1.385796e-01
325 6.347656e-01 -9.756307e-04 -1.385788e-01
326 6.367188e-01 -9.740846e-04 -1.385780e-01
327 6.386719e-01 -9.723917e-04 -1.385769e-01
328 6.406250e-01 -9.705522e-04 -1.385764e-01
329 6.425781e-01 -9.685669e-04 -1.385756e-01
330 6.445312e-01 -9.664355e-04 -1.385750e-01
331 6.464844e-01 -9.635665e-04 -1.385745e-01
332 6.484375e-01 -9.617364e-04 -1.385741e-01
333 6.503906e-01 -9.591694e-04 -1.385738e-01
334 6.523438e-01 -9.564582e-04 -1.385737e-01
335 6.542969e-01 -9.536025e-04 -1.385737e-01
336 6.562500e-01 -9.506036e-04 -1.385739e-01
337 6.582031e-01 -9.474614e-04 -1.385742e-01
338 6.601562e-01 -9.441765e-04 -1.385746e-01
339 6.621094e-01 -9.407495e-04 -1.385751e-01
340 6.640625e-01 -9.371807e-04 -1.385757e-01
341 6.660156e-01 -9.334708e-04 -1.385763e-01
342 6.679688e-01 -9.296205e-04 -1.385770e-01
343 6.699219e-01 -9.256300e-04 -1.385778e-01
344 6.718750e-01 -9.215001e-04 -1.385785e-01
345 6.738281e-01 -9.172315e-04 -1.385792e-01
346 6.757812e-01 -9.128247e-04 -1.385799e-01
347 6.777344e-01 -9.082804e-04 -1.385806e-01
348 6.796875e-01 -9.035995e-04 -1.385812e-01
349 6.816406e-01 -8.987823e-04 -1.385818e-01
350 6.835938e-01 -8.938299e-04 -1.385824e-01
351 6.855469e-01 -8.887427e-04 -1.385829e-01
352 6.875000e-01 -8.835220e-04 -1.385835e-01
353 6.894531e-01 -8.781682e-04 -1.385841e-01
354 6.914062e-01 -8.726817e-04 -1.385847e-01
355 6.933594e-01 -8.670642e-04 -1.385853e-01
356 6.953125e-01 -8.613160e-04 -1.385860e-01
357 6.972656e-01 -8.554381e-04 -1.385867e-01
358 6.992188e-01 -8.494313e-04 -1.385875e-01
359 7.011719e-01 -8.432966e-04 -1.385884e-01
360 7.031250e-01 -8.370352e-04 -1.385893e-01
361 7.050781e-01 -8.306474e-04 -1.385903e-01
362 7.070312e-01 -8.241347e-04 -1.385914e-01
363 7.089844e-01 -8.174978e-04 -1.385925e-01
364 7.109375e-01 -8.107378e-04 -1.385937e-01
365 7.128906e-01 -8.038555e-04 -1.385949e-01
366 7.148438e-01 -7.968523e-04 -1.385961e-01
367 7.167969e-01 -7.897292e-04 -1.385973e-01
368 7.187500e-01 -7.824872e-04 -1.385985e-01
369 7.207031e-01 -7.751270e-04 -1.385996e-01
370 7.226562e-01 -7.676505e-04 -1.386006e-01
371 7.246094e-01 -7.600582e-04 -1.386015e-01
372 7.265625e-01 -7.523515e-04 -1.386023e-01
373 7.285156e-01 -7.445313e-04 -1.386029e-01
374 7.304688e-01 -7.365993e-04 -1.386034e-01
375 7.324219e-01 -7.285562e-04 -1.386038e-01
376 7.343750e-01 -7.204034e-04 -1.386040e-01
377 7.363281e-01 -7.121420e-04 -1.386040e-01
378 7.382812e-01 -7.037735e-04 -1.386040e-01
379 7.402344e-01 -6.952989e-04 -1.386039e-01
380 7.421875e-01 -6.867197e-04 -1.386037e-01
381 7.441406e-01 -6.780371e-04 -1.386034e-01
382 7.460938e-01 -6.692524e-04 -1.386030e-01
383 7.480469e-01 -6.603666e-04 -1.386027e-01
384 7.500000e-01 -6.513817e-04 -1.386024e-01
385 7.519531e-01 -6.422985e-04 -1.386022e-01
386 7.539062e-01 -6.331187e-04 -1.386021e-01
387 7.558594e-01 -6.238436e-04 -1.386020e-01
388 7.578125e-01 -6.144744e-04 -1.386021e-01
389 7.597656e-01 -6.050127e-04 -1.386023e-01
390 7.617188e-01 -5.954600e-04 -1.386027e-01
391 7.636719e-01 -5.858176e-04 -1.386033e-01
392 7.656250e-01 -5.760868e-04 -1.386040e-01
393 7.675781e-01 -5.662694e-04 -1.386049e-01
394 7.695312e-01 -5.563668e-04 -1.386061e-01
395 7.714844e-01 -5.463802e-04 -1.386073e-01
396 7.734375e-01 -5.363115e-04 -1.386087e-01
397 7.753906e-01 -5.261619e-04 -1.386103e-01
398 7.773438e-01 -5.159331e-04 -1.386119e-01
399 7.792969e-01 -5.030381e-04 -1.386136e-01
400 7.812500e-01 -4.952439e-04 -1.386155e-01
401 7.832031e-01 -4.847869e-04 -1.386172e-01
402 7.851562e-01 -4.742566e-04 -1.386191e-01
403 7.871094e-01 -4.636550e-04 -1.386209e-01
404 7.890625e-01 -4.529835e-04 -1.386227e-01
405 7.910156e-01 -4.422438e-04 -1.386244e-01
406 7.929688e-01 -4.314375e-04 -1.386260e-01
407 7.949219e-01 -4.205663e-04 -1.386276e-01
408 7.968750e-01 -4.096317e-04 -1.386290e-01
409 7.988281e-01 -3.986354e-04 -1.386303e-01
410 8.007812e-01 -3.875792e-04 -1.386315e-01
411 8.027344e-01 -3.764645e-04 -1.386325e-01
412 8.046875e-01 -3.652932e-04 -1.386334e-01
413 8.066406e-01 -3.540668e-04 -1.386342e-01
414 8.085938e-01 -3.427870e-04 -1.386349e-01
415 8.105469e-01 -3.314556e-04 -1.386355e-01
416 8.125000e-01 -3.200745e-04 -1.386360e-01
417 8.144531e-01 -3.086450e-04 -1.386364e-01
418 8.164062e-01 -2.971690e-04 -1.386368e-01
419 8.183594e-01 -2.856485e-04 -1.386372e-01
420 8.203125e-01 -2.740847e-04 -1.386376e-01
421 8.222656e-01 -2.624797e-04 -1.386380e-01
422 8.242188e-01 -2.508353e-04 -1.386384e-01
423 8.261719e-01 -2.391530e-04 -1.386389e-01
424 8.281250e-01 -2.274347e-04 -1.386394e-01
425 8.300781e-01 -2.156821e-04 -1.386401e-01
426 8.320312e-01 -2.038971e-04 -1.386407e-01
427 8.339844e-01 -1.920813e-04 -1.386415e-01
428 8.359375e-01 -1.802367e-04 -1.386423e-01
429 8.378906e-01 -1.683649e-04 -1.386433e-01
430 8.398438e-01 -1.564677e-04 -1.386443e-01
431 8.417969e-01 -1.445470e-04 -1.386454e-01
432 8.437500e-01 -1.326045e-04 -1.386464e-01
433 8.457031e-01 -1.206421e-04 -1.386475e-01
434 8.476562e-01 -1.086615e-04 -1.386487e-01
435 8.496094e-01 -9.666447e-05 -1.386498e-01
436 8.515625e-01 -8.465291e-05 -1.386510e-01
437 8.535156e-01 -7.262863e-05 -1.386521e-01
438 8.554688e-01 -6.059341e-05 -1.386531e-01
439 8.574219e-01 -4.854904e-05 -1.386542e-01
440 8.593750e-01 -3.649737e-05 -1.386551e-01
441 8.613281e-01 -2.444021e-05 -1.386560e-01
442 8.632812e-01 -1.237937e-05 -1.386569e-01
443 8.652344e-01 -3.166608e-07 -1.386577e-01
444 8.671875e-01 1.174610e-05 -1.386585e-01
445 8.691406e-01 2.380708e-05 -1.386593e-01
446 8.710938e-01 3.586449e-05 -1.386600e-01
447 8.730469e-01 4.791650e-05 -1.386607e-01
448 8.750000e-01 5.996126e-05 -1.386614e-01
449 8.769531e-01 7.199703e-05 -1.386621e-01
450 8.789062e-01 8.402193e-05 -1.386629e-01
451 8.808594e-01 9.603421e-05 -1.386637e-01
452 8.828125e-01 1.080320e-04 -1.386646e-01
453 8.847656e-01 1.200135e-04 -1.386655e-01
454 8.867188e-01 1.319770e-04 -1.386666e-01
455 8.886719e-01 1.439206e-04 -1.386677e-01
456 8.906250e-01 1.558425e-04 -1.386688e-01
457 8.925781e-01 1.677409e-04 -1.386701e-01
458 8.945312e-01 1.796141e-04 -1.386714e-01
459 8.964844e-01 1.914602e-04 -1.386728e-01
460 8.984375e-01 2.032775e-04 -1.386742e-01
461 9.003906e-01 2.150641e-04 -1.386756e-01
462 9.023438e-01 2.268184e-04 -1.386771e-01
463 9.042969e-01 2.385386e-04 -1.386786e-01
464 9.062500e-01 2.502227e-04 -1.386800e-01
465 9.082031e-01 2.618693e-04 -1.386814e-01
466 9.101562e-01 2.734764e-04 -1.386827e-01
467 9.121094e-01 2.850423e-04 -1.386840e-01
468 9.140625e-01 2.965654e-04 -1.386851e-01
469 9.160156e-01 3.080436e-04 -1.386861e-01
470 9.179688e-01 3.194755e-04 -1.386870e-01
471 9.199219e-01 3.308594e-04 -1.386877e-01
472 9.218750e-01 3.421932e-04 -1.386883e-01
473 9.238281e-01 3.534758e-04 -1.386887e-01
474 9.257812e-01 3.647049e-04 -1.386890e-01
475 9.277344e-01 3.758794e-04 -1.386892e-01
476 9.296875e-01 3.869971e-04 -1.386893e-01
477 9.316406e-01 3.980565e-04 -1.386894e-01
478 9.335938e-01 4.090559e-04 -1.386893e-01
479 9.355469e-01 4.199939e-04 -1.386892e-01
480 9.375000e-01 4.308685e-04 -1.386892e-01
481 9.394531e-01 4.416781e-04 -1.386892e-01
482 9.414062e-01 4.524214e-04 -1.386892e-01
483 9.433594e-01 4.630963e-04 -1.386894e-01
484 9.453125e-01 4.737018e-04 -1.386897e-01
485 9.472656e-01 4.842359e-04 -1.386901e-01
486 9.492188e-01 4.946969e-04 -1.386907e-01
487 9.511719e-01 5.050834e-04 -1.386916e-01
488 9.531250e-01 5.153941e-04 -1.386925e-01
489 9.550781e-01 5.256268e-04 -1.386937e-01
490 9.570312e-01 5.357807e-04 -1.386951e-01
491 9.589844e-01 5.458536e-04 -1.386966e-01
492 9.609375e-01 5.558445e-04 -1.386983e-01
493 9.628906e-01 5.657516e-04 -1.387002e-01
494 9.648438e-01 5.755735e-04 -1.387021e-01
495 9.667969e-01 5.853089e-04 -1.387042e-01
496 9.687500e-01 5.949560e-04 -1.387062e-01
497 9.707031e-01 6.045135e-04 -1.387083e-01
498 9.726562e-01 6.139799e-04 -1.387103e-01
499 9.746094e-01 6.233540e-04 -1.387123e-01
500 9.765625e-01 6.326342e-04 -1.387141e-01
501 9.785156e-01 6.418190e-04 -1.387158e-01
502 9.804688e-01 6.509072e-04 -1.387174e-01
503 9.824219e-01 6.598975e-04 -1.387188e-01
504 9.843750e-01 6.687883e-04 -1.387200e-01
505 9.863281e-01 6.775784e-04 -1.387210e-01
506 9.882812e-01 6.862665e-04 -1.387218e-01
507 9.902344e-01 6.948511e-04 -1.387224e-01
508 9.921875e-01 7.033313e-04 -1.387228e-01
509 9.941406e-01 7.117054e-04 -1.387231e-01
510 9.960938e-01 7.199722e-04 -1.387232e-01
511 9.980469e-01 7.281309e-04 -1.387232e-01
Datapoint no.: 1
 #  Time [s]  Stress [Pa]  Strain [-]
TorqueRatio 9.438687e-01
AngleRatio 9.651074e-01
0 0.000000e+00 4.025208e-03 -2.698131e-03
1 1.953125e-03 5.400052e-03 -2.733662e-03
2 3.906250e-03 6.774081e-03 -2.740324e-03
3 5.859375e-03 8.147093e-03 -2.775855e-03
4 7.812500e-03 9.518875e-03 -2.746986e-03
5 9.765625e-03 1.088923e-02 -2.751428e-03
6 1.171875e-02 1.225794e-02 -2.738104e-03
7 1.367188e-02 1.362480e-02 -2.800283e-03
8 1.562500e-02 1.498961e-02 -2.806945e-03
9 1.757812e-02 1.635217e-02 -2.829152e-03
10 1.953125e-02 1.771226e-02 -2.798062e-03
11 2.148438e-02 1.906968e-02 -2.815827e-03
12 2.343750e-02 2.042423e-02 -2.784738e-03
13 2.539062e-02 2.177571e-02 -2.766972e-03
14 2.734375e-02 2.312391e-02 -2.684807e-03
15 2.929688e-02 2.446862e-02 -2.624849e-03
16 3.125000e-02 2.580966e-02 -2.520477e-03
17 3.320312e-02 2.714681e-02 -2.429429e-03
18 3.515625e-02 2.847986e-02 -2.338381e-03
19 3.710938e-02 2.980861e-02 -2.316173e-03
20 3.906250e-02 3.113289e-02 -2.313953e-03
21 4.101562e-02 3.245249e-02 -2.296188e-03
22 4.296875e-02 3.376718e-02 -2.253995e-03
23 4.492188e-02 3.507679e-02 -2.214022e-03
24 4.687500e-02 3.638113e-02 -2.198477e-03
25 4.882812e-02 3.768000e-02 -2.149622e-03
26 5.078125e-02 3.897318e-02 -2.118533e-03
27 5.273438e-02 4.026049e-02 -2.087443e-03
28 5.468750e-02 4.154173e-02 -2.114092e-03
29 5.664062e-02 4.281674e-02 -2.111871e-03
30 5.859375e-02 4.408526e-02 -2.151843e-03
31 6.054688e-02 4.534718e-02 -2.200698e-03
32 6.250000e-02 4.660224e-02 -2.298408e-03
33 6.445312e-02 4.785031e-02 -2.373911e-03
34 6.640625e-02 4.909115e-02 -2.411663e-03
35 6.835938e-02 5.032463e-02 -2.389456e-03
36 7.031250e-02 5.155049e-02 -2.369470e-03
37 7.226562e-02 5.276863e-02 -2.338381e-03
38 7.421875e-02 5.397877e-02 -2.305070e-03
39 7.617188e-02 5.518082e-02 -2.278422e-03
40 7.812500e-02 5.637454e-02 -2.242891e-03
41 8.007812e-02 5.755979e-02 -2.249553e-03
42 8.203125e-02 5.873638e-02 -2.260657e-03
43 8.398438e-02 5.990410e-02 -2.278422e-03
44 8.593750e-02 6.106280e-02 -2.278422e-03
45 8.789062e-02 6.221231e-02 -2.262877e-03
46 8.984375e-02 6.335244e-02 -2.209581e-03
47 9.179688e-02 6.448305e-02 -2.122974e-03
48 9.375000e-02 6.560395e-02 -2.023044e-03
49 9.570312e-02 6.671495e-02 -1.945319e-03
50 9.765625e-02 6.781591e-02 -1.916451e-03
51 9.960938e-02 6.890667e-02 -1.918671e-03
52 1.015625e-01 6.998704e-02 -1.931995e-03
53 1.035156e-01 7.105687e-02 -1.929775e-03
54 1.054688e-01 7.211600e-02 -1.967526e-03
55 1.074219e-01 7.316428e-02 -1.994175e-03
56 1.093750e-01 7.420154e-02 -2.025264e-03
57 1.113281e-01 7.522760e-02 -1.976409e-03
58 1.132812e-01 7.624236e-02 -1.938657e-03
59 1.152344e-01 7.724565e-02 -1.863154e-03
60 1.171875e-01 7.823728e-02 -1.829844e-03
61 1.191406e-01 7.921711e-02 -1.794313e-03
62 1.210938e-01 8.018505e-02 -1.818740e-03
63 1.230469e-01 8.114090e-02 -1.872037e-03
64 1.250000e-01 8.208452e-02 -1.943099e-03
65 1.269531e-01 8.301578e-02 -1.980851e-03
66 1.289062e-01 8.393455e-02 -1.996395e-03
67 1.308594e-01 8.484067e-02 -1.994175e-03
68 1.328125e-01 8.573402e-02 -1.976409e-03
69 1.347656e-01 8.661446e-02 -1.912009e-03
70 1.367188e-01 8.748186e-02 -1.834285e-03
71 1.386719e-01 8.833606e-02 -1.780989e-03
72 1.406250e-01 8.917700e-02 -1.738796e-03
73 1.425781e-01 9.000447e-02 -1.718809e-03
74 1.445312e-01 9.081841e-02 -1.725472e-03
75 1.464844e-01 9.161866e-02 -1.780989e-03
76 1.484375e-01 9.240512e-02 -1.814299e-03
77 1.503906e-01 9.317766e-02 -1.825402e-03
78 1.523438e-01 9.393616e-02 -1.765444e-03
79 1.542969e-01 9.468053e-02 -1.734355e-03
80 1.562500e-01 9.541062e-02 -1.658851e-03
81 1.582031e-01 9.612636e-02 -1.598893e-03
82 1.601562e-01 9.682763e-02 -1.527831e-03
83 1.621094e-01 9.751429e-02 -1.503403e-03
84 1.640625e-01 9.818629e-02 -1.527831e-03
85 1.660156e-01 9.884350e-02 -1.585568e-03
86 1.679688e-01 9.948581e-02 -1.638865e-03
87 1.699219e-01 1.001132e-01 -1.705486e-03
88 1.718750e-01 1.007254e-01 -1.761003e-03
89 1.738281e-01 1.013225e-01 -1.778768e-03
90 1.757812e-01 1.019043e-01 -1.743237e-03
91 1.777344e-01 1.024708e-01 -1.683279e-03
92 1.796875e-01 1.030219e-01 -1.652189e-03
93 1.816406e-01 1.035574e-01 -1.607775e-03
94 1.835938e-01 1.040774e-01 -1.609996e-03
95 1.855469e-01 1.045817e-01 -1.612217e-03
96 1.875000e-01 1.050702e-01 -1.676617e-03
97 1.894531e-01 1.055429e-01 -1.712148e-03
98 1.914062e-01 1.059997e-01 -1.761003e-03
99 1.933594e-01 1.064405e-01 -1.749899e-03
100 1.953125e-01 1.068653e-01 -1.734355e-03
101 1.972656e-01 1.072740e-01 -1.667734e-03
102 1.992188e-01 1.076666e-01 -1.587789e-03
103 2.011719e-01 1.080429e-01 -1.487859e-03
104 2.031250e-01 1.084030e-01 -1.421238e-03
105 2.050781e-01 1.087468e-01 -1.394590e-03
106 2.070312e-01 1.090742e-01 -1.403472e-03
107 2.089844e-01 1.093851e-01 -1.450107e-03
108 2.109375e-01 1.096796e-01 -1.512286e-03
109 2.128906e-01 1.099575e-01 -1.572244e-03
110 2.148438e-01 1.102189e-01 -1.587789e-03
111 2.167969e-01 1.104637e-01 -1.603334e-03
112 2.187500e-01 1.106919e-01 -1.552258e-03
113 2.207031e-01 1.109034e-01 -1.510065e-03
114 2.226562e-01 1.110982e-01 -1.445665e-03
115 2.246094e-01 1.112763e-01 -1.445665e-03
116 2.265625e-01 1.114376e-01 -1.430121e-03
117 2.285156e-01 1.115821e-01 -1.490079e-03
118 2.304688e-01 1.117098e-01 -1.527831e-03
119 2.324219e-01 1.118207e-01 -1.614437e-03
120 2.343750e-01 1.119148e-01 -1.658851e-03
121 2.363281e-01 1.119920e-01 -1.669955e-03
122 2.382812e-01 1.120523e-01 -1.638865e-03
123 2.402344e-01 1.120958e-01 -1.587789e-03
124 2.421875e-01 1.121224e-01 -1.505624e-03
125 2.441406e-01 1.121321e-01 -1.407914e-03
126 2.460938e-01 1.121249e-01 -1.350176e-03
127 2.480469e-01 1.121008e-01 -1.325749e-03
128 2.500000e-01 1.120598e-01 -1.354618e-03
129 2.519531e-01 1.120020e-01 -1.385707e-03
130 2.539062e-01 1.119273e-01 -1.445665e-03
131 2.558594e-01 1.118358e-01 -1.476755e-03
132 2.578125e-01 1.117273e-01 -1.510065e-03
133 2.597656e-01 1.116021e-01 -1.470093e-03
134 2.617188e-01 1.114601e-01 -1.430121e-03
135 2.636719e-01 1.113013e-01 -1.370162e-03
136 2.656250e-01 1.111257e-01 -1.361279e-03
137 2.675781e-01 1.109334e-01 -1.319087e-03
138 2.695312e-01 1.107244e-01 -1.339073e-03
139 2.714844e-01 1.104987e-01 -1.405693e-03
140 2.734375e-01 1.102563e-01 -1.527831e-03
141 2.753906e-01 1.099974e-01 -1.598893e-03
142 2.773438e-01 1.095897e-01 -1.656630e-03
143 2.792969e-01 1.092980e-01 -1.683279e-03
144 2.812500e-01 1.089898e-01 -1.685499e-03
145 2.832031e-01 1.086653e-01 -1.672175e-03
146 2.851562e-01 1.083244e-01 -1.592231e-03
147 2.871094e-01 1.079672e-01 -1.534493e-03
148 2.890625e-01 1.075937e-01 -1.514507e-03
149 2.910156e-01 1.072040e-01 -1.521169e-03
150 2.929688e-01 1.067981e-01 -1.543376e-03
151 2.949219e-01 1.063762e-01 -1.592231e-03
152 2.968750e-01 1.059383e-01 -1.634424e-03
153 2.988281e-01 1.054844e-01 -1.674396e-03
154 3.007812e-01 1.050146e-01 -1.656630e-03
155 3.027344e-01 1.045290e-01 -1.596672e-03
156 3.046875e-01 1.040277e-01 -1.516727e-03
157 3.066406e-01 1.035107e-01 -1.458990e-03
158 3.085938e-01 1.029781e-01 -1.383486e-03
159 3.105469e-01 1.024300e-01 -1.319087e-03
160 3.125000e-01 1.018665e-01 -1.323528e-03
161 3.144531e-01 1.012876e-01 -1.374603e-03
162 3.164062e-01 1.006935e-01 -1.432341e-03
163 3.183594e-01 1.000843e-01 -1.478976e-03
164 3.203125e-01 9.945989e-02 -1.536714e-03
165 3.222656e-01 9.882055e-02 -1.563362e-03
166 3.242188e-01 9.816635e-02 -1.565582e-03
167 3.261719e-01 9.749737e-02 -1.545596e-03
168 3.281250e-01 9.681366e-02 -1.496741e-03
169 3.300781e-01 9.611542e-02 -1.483417e-03
170 3.320312e-01 9.540268e-02 -1.490079e-03
171 3.339844e-01 9.467559e-02 -1.532272e-03
172 3.359375e-01 9.393422e-02 -1.596672e-03
173 3.378906e-01 9.317870e-02 -1.692162e-03
174 3.398438e-01 9.240916e-02 -1.749899e-03
175 3.417969e-01 9.162572e-02 -1.800975e-03
176 3.437500e-01 9.082847e-02 -1.809858e-03
177 3.457031e-01 9.001753e-02 -1.807637e-03
178 3.476562e-01 8.919304e-02 -1.738796e-03
179 3.496094e-01 8.835514e-02 -1.672175e-03
180 3.515625e-01 8.750392e-02 -1.609996e-03
181 3.535156e-01 8.663950e-02 -1.601113e-03
182 3.554688e-01 8.576207e-02 -1.614437e-03
183 3.574219e-01 8.487169e-02 -1.649968e-03
184 3.593750e-01 8.396855e-02 -1.674396e-03
185 3.613281e-01 8.305277e-02 -1.721030e-03
186 3.632812e-01 8.212445e-02 -1.772106e-03
187 3.652344e-01 8.118378e-02 -1.765444e-03
188 3.671875e-01 8.023090e-02 -1.738796e-03
189 3.691406e-01 7.926592e-02 -1.676617e-03
190 3.710938e-01 7.828900e-02 -1.654410e-03
191 3.730469e-01 7.730030e-02 -1.625541e-03
192 3.750000e-01 7.629997e-02 -1.643306e-03
193 3.769531e-01 7.528812e-02 -1.658851e-03
194 3.789062e-01 7.426495e-02 -1.749899e-03
195 3.808594e-01 7.323058e-02 -1.816520e-03
196 3.828125e-01 7.218520e-02 -1.900906e-03
197 3.847656e-01 7.112895e-02 -1.938657e-03
198 3.867188e-01 7.006198e-02 -1.963085e-03
199 3.886719e-01 6.898446e-02 -1.965306e-03
200 3.906250e-01 6.789657e-02 -1.934216e-03
201 3.925781e-01 6.679843e-02 -1.887582e-03
202 3.945312e-01 6.569023e-02 -1.858713e-03
203 3.964844e-01 6.457214e-02 -1.872037e-03
204 3.984375e-01 6.344435e-02 -1.880920e-03
205 4.003906e-01 6.230697e-02 -1.936437e-03
206 4.023438e-01 6.116023e-02 -1.967526e-03
207 4.042969e-01 6.000428e-02 -2.031926e-03
208 4.062500e-01 5.883929e-02 -2.029705e-03
209 4.082031e-01 5.766542e-02 -2.038588e-03
210 4.101562e-01 5.648289e-02 -1.978630e-03
211 4.121094e-01 5.529184e-02 -1.967526e-03
212 4.140625e-01 5.409246e-02 -1.909789e-03
213 4.160156e-01 5.288494e-02 -1.896464e-03
214 4.179688e-01 5.166947e-02 -1.863154e-03
215 4.199219e-01 5.044622e-02 -1.898685e-03
216 4.218750e-01 4.921534e-02 -1.960864e-03
217 4.238281e-01 4.797706e-02 -2.027485e-03
218 4.257812e-01 4.673157e-02 -2.078561e-03
219 4.277344e-01 4.547904e-02 -2.100767e-03
220 4.296875e-01 4.421964e-02 -2.120754e-03
221 4.316406e-01 4.295361e-02 -2.105209e-03
222 4.335938e-01 4.168110e-02 -2.096326e-03
223 4.355469e-01 4.040231e-02 -2.049692e-03
224 4.375000e-01 3.911745e-02 -2.056353e-03
225 4.394531e-01 3.782666e-02 -2.063016e-03
226 4.414062e-01 3.653020e-02 -2.114092e-03
227 4.433594e-01 3.522825e-02 -2.138519e-03
228 4.453125e-01 3.392097e-02 -2.214022e-03
229 4.472656e-01 3.260860e-02 -2.249553e-03
230 4.492188e-01 3.129131e-02 -2.293967e-03
231 4.511719e-01 2.996932e-02 -2.276201e-03
232 4.531250e-01 2.864282e-02 -2.265098e-03
233 4.550781e-01 2.731199e-02 -2.240671e-03
234 4.570312e-01 2.597705e-02 -2.214022e-03
235 4.589844e-01 2.463820e-02 -2.218463e-03
236 4.609375e-01 2.329564e-02 -2.205139e-03
237 4.628906e-01 2.194957e-02 -2.249553e-03
238 4.648438e-01 2.060019e-02 -2.269540e-03
239 4.667969e-01 1.924771e-02 -2.333939e-03
240 4.687500e-01 1.789234e-02 -2.347264e-03
241 4.707031e-01 1.653427e-02 -2.385015e-03
242 4.726562e-01 1.517371e-02 -2.378353e-03
243 4.746094e-01 1.381086e-02 -2.387235e-03
244 4.765625e-01 1.244593e-02 -2.378353e-03
245 4.785156e-01 1.107913e-02 -2.380574e-03
246 4.804688e-01 9.710668e-03 -2.389456e-03
247 4.824219e-01 8.340735e-03 -2.416104e-03
248 4.843750e-01 6.969551e-03 -2.447194e-03
249 4.863281e-01 5.597313e-03 -2.487166e-03
250 4.882812e-01 4.224234e-03 -2.518256e-03
251 4.902344e-01 2.850518e-03 -2.536022e-03
252 4.921875e-01 1.476374e-03 -2.560449e-03
253 4.941406e-01 1.020070e-04 -2.569332e-03
254 4.960938e-01 -1.272375e-03 -2.600421e-03
255 4.980469e-01 -2.646565e-03 -2.580435e-03
256 5.000000e-01 -4.020358e-03 -2.598201e-03
257 5.019531e-01 -5.393544e-03 -2.578215e-03
258 5.039062e-01 -6.765920e-03 -2.620408e-03
259 5.058594e-01 -8.137274e-03 -2.629290e-03
260 5.078125e-01 -9.507404e-03 -2.680366e-03
261 5.097656e-01 -1.087610e-02 -2.667041e-03
262 5.117188e-01 -1.224316e-02 -2.675924e-03
263 5.136719e-01 -1.360838e-02 -2.647056e-03
264 5.156250e-01 -1.497155e-02 -2.671483e-03
265 5.175781e-01 -1.633246e-02 -2.644835e-03
266 5.195312e-01 -1.769091e-02 -2.655939e-03
267 5.214844e-01 -1.904670e-02 -2.649277e-03
268 5.234375e-01 -2.039962e-02 -2.687028e-03
269 5.253906e-01 -2.174947e-02 -2.727000e-03
270 5.273438e-01 -2.309605e-02 -2.766972e-03
271 5.292969e-01 -2.443914e-02 -2.809166e-03
272 5.312500e-01 -2.577855e-02 -2.853579e-03
273 5.332031e-01 -2.711409e-02 -2.891331e-03
274 5.351562e-01 -2.844554e-02 -2.858021e-03
275 5.371094e-01 -2.977271e-02 -2.851359e-03
276 5.390625e-01 -3.109539e-02 -2.813607e-03
277 5.410156e-01 -3.241337e-02 -2.833593e-03
278 5.429688e-01 -3.372650e-02 -2.831373e-03
279 5.449219e-01 -3.503453e-02 -2.844697e-03
280 5.468750e-01 -3.633729e-02 -2.878007e-03
281 5.488281e-01 -3.763459e-02 -2.933523e-03
282 5.507812e-01 -3.892620e-02 -2.989041e-03
283 5.527344e-01 -4.021197e-02 -2.982379e-03
284 5.546875e-01 -4.149167e-02 -2.995703e-03
285 5.566406e-01 -4.276512e-02 -2.993482e-03
286 5.585938e-01 -4.403213e-02 -2.989041e-03
287 5.605469e-01 -4.529252e-02 -2.920199e-03
288 5.625000e-01 -4.654609e-02 -2.895771e-03
289 5.644531e-01 -4.779265e-02 -2.920199e-03
290 5.664062e-01 -4.903200e-02 -2.977937e-03
291 5.683594e-01 -5.026397e-02 -3.020131e-03
292 5.703125e-01 -5.148837e-02 -3.073428e-03
293 5.722656e-01 -5.270502e-02 -3.151150e-03
294 5.742188e-01 -5.391374e-02 -3.211109e-03
295 5.761719e-01 -5.511434e-02 -3.224433e-03
296 5.781250e-01 -5.630662e-02 -3.193344e-03
297 5.800781e-01 -5.749044e-02 -3.197785e-03
298 5.820312e-01 -5.866560e-02 -3.186681e-03
299 5.839844e-01 -5.983191e-02 -3.184461e-03
300 5.859375e-01 -6.098922e-02 -3.157812e-03
301 5.878906e-01 -6.213733e-02 -3.213330e-03
302 5.898438e-01 -6.327610e-02 -3.275510e-03
303 5.917969e-01 -6.440535e-02 -3.353235e-03
304 5.937500e-01 -6.552489e-02 -3.379880e-03
305 5.957031e-01 -6.663456e-02 -3.422074e-03
306 5.976562e-01 -6.773420e-02 -3.395425e-03
307 5.996094e-01 -6.882364e-02 -3.357673e-03
308 6.015625e-01 -6.990271e-02 -3.293276e-03
309 6.035156e-01 -7.097124e-02 -3.235537e-03
310 6.054688e-01 -7.202909e-02 -3.208888e-03
311 6.074219e-01 -7.307612e-02 -3.188902e-03
312 6.093750e-01 -7.411212e-02 -3.191123e-03
313 6.113281e-01 -7.513696e-02 -3.215551e-03
314 6.132812e-01 -7.615049e-02 -3.271068e-03
315 6.152344e-01 -7.715254e-02 -3.324365e-03
316 6.171875e-01 -7.814298e-02 -3.362115e-03
317 6.191406e-01 -7.912166e-02 -3.346573e-03
318 6.210938e-01 -8.008841e-02 -3.304379e-03
319 6.230469e-01 -8.104312e-02 -3.268848e-03
320 6.250000e-01 -8.198562e-02 -3.246641e-03
321 6.269531e-01 -8.291575e-02 -3.248861e-03
322 6.289062e-01 -8.383341e-02 -3.275510e-03
323 6.308594e-01 -8.473844e-02 -3.355453e-03
324 6.328125e-01 -8.563071e-02 -3.448723e-03
325 6.347656e-01 -8.651008e-02 -3.557537e-03
326 6.367188e-01 -8.737643e-02 -3.635259e-03
327 6.386719e-01 -8.822961e-02 -3.708543e-03
328 6.406250e-01 -8.906952e-02 -3.710764e-03
329 6.425781e-01 -8.989602e-02 -3.739633e-03
330 6.445312e-01 -9.070895e-02 -3.675232e-03
331 6.464844e-01 -9.150825e-02 -3.657466e-03
332 6.484375e-01 -9.229377e-02 -3.626376e-03
333 6.503906e-01 -9.306537e-02 -3.637480e-03
334 6.523438e-01 -9.382296e-02 -3.648584e-03
335 6.542969e-01 -9.456644e-02 -3.721867e-03
336 6.562500e-01 -9.529567e-02 -3.759619e-03
337 6.582031e-01 -9.601052e-02 -3.775164e-03
338 6.601562e-01 -9.671096e-02 -3.755178e-03
339 6.621094e-01 -9.739679e-02 -3.699660e-03
340 6.640625e-01 -9.806798e-02 -3.633038e-03
341 6.660156e-01 -9.872438e-02 -3.541992e-03
342 6.679688e-01 -9.936592e-02 -3.450943e-03
343 6.699219e-01 -9.999251e-02 -3.366556e-03
344 6.718750e-01 -1.006040e-01 -3.366556e-03
345 6.738281e-01 -1.012004e-01 -3.375439e-03
346 6.757812e-01 -1.017815e-01 -3.448723e-03
347 6.777344e-01 -1.023474e-01 -3.479812e-03
348 6.796875e-01 -1.028978e-01 -3.579742e-03
349 6.816406e-01 -1.034326e-01 -3.597507e-03
350 6.835938e-01 -1.039520e-01 -3.606390e-03
351 6.855469e-01 -1.044556e-01 -3.568641e-03
352 6.875000e-01 -1.049436e-01 -3.577521e-03
353 6.894531e-01 -1.054157e-01 -3.584186e-03
354 6.914062e-01 -1.058719e-01 -3.619714e-03
355 6.933594e-01 -1.063122e-01 -3.688556e-03
356 6.953125e-01 -1.067365e-01 -3.755178e-03
357 6.972656e-01 -1.071448e-01 -3.910625e-03
358 6.992188e-01 -1.075369e-01 -3.992791e-03
359 7.011719e-01 -1.079127e-01 -4.090500e-03
360 7.031250e-01 -1.082724e-01 -4.099382e-03
361 7.050781e-01 -1.086157e-01 -4.137135e-03
362 7.070312e-01 -1.089427e-01 -4.061630e-03
363 7.089844e-01 -1.092533e-01 -4.003895e-03
364 7.109375e-01 -1.095474e-01 -3.883976e-03
365 7.128906e-01 -1.098250e-01 -3.857328e-03
366 7.148438e-01 -1.100861e-01 -3.828461e-03
367 7.167969e-01 -1.103306e-01 -3.841783e-03
368 7.187500e-01 -1.105585e-01 -3.837341e-03
369 7.207031e-01 -1.107698e-01 -3.859549e-03
370 7.226562e-01 -1.109643e-01 -3.848445e-03
371 7.246094e-01 -1.111422e-01 -3.797371e-03
372 7.265625e-01 -1.113033e-01 -3.730750e-03
373 7.285156e-01 -1.114476e-01 -3.606390e-03
374 7.304688e-01 -1.115752e-01 -3.535330e-03
375 7.324219e-01 -1.116860e-01 -3.450943e-03
376 7.343750e-01 -1.117799e-01 -3.448723e-03
377 7.363281e-01 -1.118570e-01 -3.428736e-03
378 7.382812e-01 -1.119173e-01 -3.535330e-03
379 7.402344e-01 -1.119607e-01 -3.626376e-03
380 7.421875e-01 -1.119873e-01 -3.741854e-03
381 7.441406e-01 -1.119969e-01 -3.806251e-03
382 7.460938e-01 -1.119897e-01 -3.868431e-03
383 7.480469e-01 -1.119657e-01 -3.888418e-03
384 7.500000e-01 -1.119248e-01 -3.908404e-03
385 7.519531e-01 -1.118670e-01 -3.870652e-03
386 7.539062e-01 -1.117924e-01 -3.861769e-03
387 7.558594e-01 -1.117010e-01 -3.895080e-03
[...]
60 1.171875e-01 4.590456e+01 9.858917e+01
61 1.191406e-01 4.616703e+01 9.842354e+01
62 1.210938e-01 4.668000e+01 9.836333e+01
63 1.230469e-01 4.669137e+01 9.824034e+01
64 1.250000e-01 4.694059e+01 9.811316e+01
65 1.269531e-01 4.662700e+01 9.790339e+01
66 1.289062e-01 4.615409e+01 9.783152e+01
67 1.308594e-01 4.553094e+01 9.767857e+01
68 1.328125e-01 4.514699e+01 9.751667e+01
69 1.347656e-01 4.421273e+01 9.734505e+01
70 1.367188e-01 4.356193e+01 9.716663e+01
71 1.386719e-01 4.238013e+01 9.697309e+01
72 1.406250e-01 4.109579e+01 9.676715e+01
73 1.425781e-01 3.973120e+01 9.654781e+01
74 1.445312e-01 3.869362e+01 9.631400e+01
75 1.464844e-01 3.714211e+01 9.606479e+01
76 1.484375e-01 3.594902e+01 9.580461e+01
77 1.503906e-01 3.424987e+01 9.552183e+01
78 1.523438e-01 3.247248e+01 9.522074e+01
79 1.542969e-01 3.104188e+01 9.490066e+01
80 1.562500e-01 2.909513e+01 9.456066e+01
81 1.582031e-01 2.708030e+01 9.420006e+01
82 1.601562e-01 2.546186e+01 9.382625e+01
83 1.621094e-01 2.335718e+01 9.342320e+01
84 1.640625e-01 2.125136e+01 9.278192e+01
85 1.660156e-01 1.958981e+01 9.255093e+01
86 1.679688e-01 1.750160e+01 9.208109e+01
87 1.699219e-01 1.546624e+01 9.158863e+01
88 1.718750e-01 1.394980e+01 9.108436e+01
89 1.738281e-01 1.203974e+01 9.054748e+01
90 1.757812e-01 1.022113e+01 8.970694e+01
91 1.777344e-01 8.942770e+00 8.940819e+01
92 1.796875e-01 7.298611e+00 8.880697e+01
93 1.816406e-01 6.213464e+00 8.819847e+01
94 1.835938e-01 4.750159e+00 8.755805e+01
95 1.855469e-01 3.391073e+00 8.689922e+01
96 1.875000e-01 2.148832e+00 8.588519e+01
97 1.894531e-01 1.469985e+00 8.552932e+01
98 1.914062e-01 4.473729e-01 8.481938e+01
99 1.933594e-01 -7.133981e-04 8.410880e+01
100 1.953125e-01 -8.013062e-01 8.298555e+01
101 1.972656e-01 -1.490459e+00 8.261452e+01
102 1.992188e-01 -1.643227e+00 8.184775e+01
103 2.011719e-01 -2.164868e+00 8.068499e+01
104 2.031250e-01 -2.588448e+00 7.989172e+01
105 2.050781e-01 -2.474503e+00 7.949964e+01
106 2.070312e-01 -2.740399e+00 7.869200e+01
107 2.089844e-01 -2.923480e+00 7.787502e+01
108 2.109375e-01 -2.592545e+00 7.658100e+01
109 2.128906e-01 -2.629423e+00 7.621533e+01
110 2.148438e-01 -2.589975e+00 7.495824e+01
111 2.167969e-01 -2.043516e+00 7.454129e+01
112 2.187500e-01 -1.892074e+00 7.324530e+01
113 2.207031e-01 -1.678573e+00 7.239598e+01
114 2.226562e-01 -1.000028e+00 7.152182e+01
115 2.246094e-01 -7.364257e-01 7.064072e+01
116 2.265625e-01 -3.203063e-02 6.975257e+01
117 2.285156e-01 2.180845e-01 6.885698e+01
118 2.304688e-01 4.487187e-01 6.795404e+01
119 2.324219e-01 6.438144e-01 6.706277e+01
120 2.343750e-01 1.205538e+00 6.614587e+01
121 2.363281e-01 1.274239e+00 6.522165e+01
122 2.382812e-01 1.700222e+00 6.429037e+01
123 2.402344e-01 1.615510e+00 6.335192e+01
124 2.421875e-01 1.459983e+00 6.288966e+01
125 2.441406e-01 1.233963e+00 6.147407e+01
126 2.460938e-01 1.338978e+00 6.051572e+01
127 2.480469e-01 9.340578e-01 5.955010e+01
128 2.500000e-01 8.748078e-01 5.857632e+01
129 2.519531e-01 3.090719e-01 5.759397e+01
130 2.539062e-01 -3.221443e-01 5.660296e+01
131 2.558594e-01 -6.118916e-01 5.562397e+01
132 2.578125e-01 -1.378837e+00 5.461618e+01
133 2.597656e-01 -2.189832e+00 5.359924e+01
134 2.617188e-01 -2.636329e+00 5.257287e+01
135 2.636719e-01 -3.560526e+00 5.153649e+01
136 2.656250e-01 -4.524945e+00 5.051116e+01
137 2.675781e-01 -5.120062e+00 4.945413e+01
138 2.695312e-01 -6.153194e+00 4.838665e+01
139 2.714844e-01 -7.196297e+00 4.730849e+01
140 2.734375e-01 -7.833385e+00 4.621927e+01
141 2.753906e-01 -8.868379e+00 4.511873e+01
142 2.773438e-01 -9.868338e+00 4.402964e+01
143 2.792969e-01 -1.044471e+01 4.290683e+01
144 2.812500e-01 -1.136311e+01 4.177302e+01
145 2.832031e-01 -1.179439e+01 4.062827e+01
146 2.851562e-01 -1.252223e+01 3.947292e+01
147 2.871094e-01 -1.314449e+01 3.830753e+01
148 2.890625e-01 -1.365071e+01 3.715636e+01
149 2.910156e-01 -1.365700e+01 3.597158e+01
150 2.929688e-01 -1.390307e+01 3.477751e+01
151 2.949219e-01 -1.365724e+01 3.357523e+01
152 2.968750e-01 -1.369103e+01 3.236539e+01
153 2.988281e-01 -1.363960e+01 3.114836e+01
154 3.007812e-01 -1.350846e+01 2.994995e+01
155 3.027344e-01 -1.297943e+01 2.872085e+01
156 3.046875e-01 -1.276000e+01 2.748663e+01
157 3.066406e-01 -1.216601e+01 2.624817e+01
158 3.085938e-01 -1.191039e+01 2.500623e+01
159 3.105469e-01 -1.164656e+01 2.376129e+01
160 3.125000e-01 -1.106114e+01 2.253909e+01
161 3.144531e-01 -1.081464e+01 2.128909e+01
162 3.164062e-01 -1.057702e+01 2.003712e+01
163 3.183594e-01 -1.004258e+01 1.878348e+01
164 3.203125e-01 -9.868525e+00 1.752906e+01
165 3.222656e-01 -9.732903e+00 1.630037e+01
166 3.242188e-01 -9.342731e+00 1.504691e+01
167 3.261719e-01 -9.312521e+00 1.379464e+01
168 3.281250e-01 -9.326660e+00 1.254430e+01
169 3.300781e-01 -9.087651e+00 1.129666e+01
170 3.320312e-01 -9.192785e+00 1.005215e+01
171 3.339844e-01 -9.326528e+00 8.836023e+00
172 3.359375e-01 -9.218482e+00 7.597775e+00
173 3.378906e-01 -9.439102e+00 6.362916e+00
174 3.398438e-01 -9.422769e+00 5.131278e+00
175 3.417969e-01 -9.734933e+00 3.902421e+00
176 3.437500e-01 -1.008093e+01 2.676159e+00
177 3.457031e-01 -1.044973e+01 1.477229e+00
178 3.476562e-01 -1.057455e+01 2.556774e-01
179 3.496094e-01 -1.097208e+01 -9.636426e-01
180 3.515625e-01 -1.146458e+01 -2.181121e+00
181 3.535156e-01 -1.175657e+01 -3.396906e+00
182 3.554688e-01 -1.233872e+01 -4.610923e+00
183 3.574219e-01 -1.293419e+01 -5.798667e+00
184 3.593750e-01 -1.354287e+01 -7.009777e+00
185 3.613281e-01 -1.425124e+01 -8.219556e+00
186 3.632812e-01 -1.488857e+01 -9.427601e+00
187 3.652344e-01 -1.498181e+01 -1.063384e+01
188 3.671875e-01 -1.563996e+01 -1.183860e+01
189 3.691406e-01 -1.641367e+01 -1.301748e+01
190 3.710938e-01 -1.674708e+01 -1.421969e+01
191 3.730469e-01 -1.740981e+01 -1.542015e+01
192 3.750000e-01 -1.805844e+01 -1.661872e+01
193 3.769531e-01 -1.849325e+01 -1.781536e+01
194 3.789062e-01 -1.912242e+01 -1.898502e+01
195 3.808594e-01 -1.973563e+01 -2.017664e+01
196 3.828125e-01 -2.014736e+01 -2.136610e+01
197 3.847656e-01 -2.073356e+01 -2.255326e+01
198 3.867188e-01 -2.157367e+01 -2.373789e+01
199 3.886719e-01 -2.193771e+01 -2.492031e+01
200 3.906250e-01 -2.219866e+01 -2.607698e+01
201 3.925781e-01 -2.269141e+01 -2.725589e+01
202 3.945312e-01 -2.299480e+01 -2.843198e+01
203 3.964844e-01 -2.342522e+01 -2.960493e+01
204 3.984375e-01 -2.367410e+01 -3.077502e+01
205 4.003906e-01 -2.420548e+01 -3.194143e+01
206 4.023438e-01 -2.436310e+01 -3.307904e+01
207 4.042969e-01 -2.463531e+01 -3.423479e+01
208 4.062500e-01 -2.484840e+01 -3.538439e+01
209 4.082031e-01 -2.500421e+01 -3.652695e+01
210 4.101562e-01 -2.499747e+01 -3.766151e+01
211 4.121094e-01 -2.505266e+01 -3.876550e+01
212 4.140625e-01 -2.496090e+01 -3.988581e+01
213 4.160156e-01 -2.492292e+01 -4.099928e+01
214 4.179688e-01 -2.483344e+01 -4.210536e+01
215 4.199219e-01 -2.469252e+01 -4.320378e+01
216 4.218750e-01 -2.442932e+01 -4.429476e+01
217 4.238281e-01 -2.419675e+01 -4.535557e+01
218 4.257812e-01 -2.385748e+01 -4.643034e+01
219 4.277344e-01 -2.354649e+01 -4.749699e+01
220 4.296875e-01 -2.320069e+01 -4.855552e+01
221 4.316406e-01 -2.278529e+01 -4.960592e+01
222 4.335938e-01 -2.240458e+01 -5.064788e+01
223 4.355469e-01 -2.201514e+01 -5.165974e+01
224 4.375000e-01 -2.160085e+01 -5.268348e+01
225 4.394531e-01 -2.123161e+01 -5.369796e+01
226 4.414062e-01 -2.087935e+01 -5.470302e+01
227 4.433594e-01 -2.054239e+01 -5.569883e+01
228 4.453125e-01 -2.025518e+01 -5.668510e+01
229 4.472656e-01 -2.001244e+01 -5.764192e+01
230 4.492188e-01 -1.982858e+01 -5.860937e+01
231 4.511719e-01 -1.970884e+01 -5.956742e+01
232 4.531250e-01 -1.967146e+01 -6.051569e+01
233 4.550781e-01 -1.974891e+01 -6.145483e+01
234 4.570312e-01 -1.993137e+01 -6.238522e+01
235 4.589844e-01 -2.028246e+01 -6.328803e+01
236 4.609375e-01 -2.077265e+01 -6.420119e+01
237 4.628906e-01 -2.144716e+01 -6.510619e+01
238 4.648438e-01 -2.231911e+01 -6.600319e+01
239 4.667969e-01 -2.343125e+01 -6.689240e+01
240 4.687500e-01 -2.472186e+01 -6.775640e+01
241 4.707031e-01 -2.626370e+01 -6.863143e+01
242 4.726562e-01 -2.796834e+01 -6.949910e+01
243 4.746094e-01 -2.986718e+01 -7.035888e+01
244 4.765625e-01 -3.198944e+01 -7.121054e+01
245 4.785156e-01 -3.422252e+01 -7.205420e+01
246 4.804688e-01 -3.658809e+01 -7.287226e+01
247 4.824219e-01 -3.911709e+01 -7.369872e+01
248 4.843750e-01 -4.166757e+01 -7.451633e+01
249 4.863281e-01 -4.426524e+01 -7.532472e+01
250 4.882812e-01 -4.694236e+01 -7.612318e+01
251 4.902344e-01 -4.954069e+01 -7.691164e+01
252 4.921875e-01 -5.209230e+01 -7.767367e+01
253 4.941406e-01 -5.465052e+01 -7.843989e+01
254 4.960938e-01 -5.701718e+01 -7.919370e+01
255 4.980469e-01 -5.924669e+01 -7.993507e+01
256 5.000000e-01 -6.140459e+01 -8.066390e+01
257 5.019531e-01 -6.328046e+01 -8.137975e+01
258 5.039062e-01 -6.506183e+01 -8.206811e+01
259 5.058594e-01 -6.650380e+01 -8.275791e+01
260 5.078125e-01 -6.770132e+01 -8.343476e+01
261 5.097656e-01 -6.864068e+01 -8.409838e+01
262 5.117188e-01 -6.945052e+01 -8.474865e+01
263 5.136719e-01 -6.985525e+01 -8.537267e+01
264 5.156250e-01 -7.014999e+01 -8.599622e+01
265 5.175781e-01 -7.001676e+01 -8.660603e+01
266 5.195312e-01 -6.961579e+01 -8.720174e+01
267 5.214844e-01 -6.895576e+01 -8.778308e+01
268 5.234375e-01 -6.823254e+01 -8.835005e+01
269 5.253906e-01 -6.709601e+01 -8.889145e+01
270 5.273438e-01 -6.595469e+01 -8.942992e+01
271 5.292969e-01 -6.441762e+01 -8.995396e+01
272 5.312500e-01 -6.272193e+01 -9.046372e+01
273 5.332031e-01 -6.111233e+01 -9.095914e+01
274 5.351562e-01 -5.917406e+01 -9.144041e+01
275 5.371094e-01 -5.716231e+01 -9.189805e+01
276 5.390625e-01 -5.535285e+01 -9.235125e+01
277 5.410156e-01 -5.325706e+01 -9.279011e+01
278 5.429688e-01 -5.114309e+01 -9.321448e+01
279 5.449219e-01 -4.929376e+01 -9.362420e+01
280 5.468750e-01 -4.720601e+01 -9.401906e+01
281 5.488281e-01 -4.517264e+01 -9.439111e+01
282 5.507812e-01 -4.351385e+01 -9.475585e+01
283 5.527344e-01 -4.169536e+01 -9.510516e+01
284 5.546875e-01 -4.001367e+01 -9.543891e+01
285 5.566406e-01 -3.875361e+01 -9.575704e+01
286 5.585938e-01 -3.734361e+01 -9.605943e+01
287 5.605469e-01 -3.636475e+01 -9.634043e+01
288 5.625000e-01 -3.522512e+01 -9.661159e+01
289 5.644531e-01 -3.423730e+01 -9.686670e+01
290 5.664062e-01 -3.339449e+01 -9.710585e+01
291 5.683594e-01 -3.299701e+01 -9.732896e+01
292 5.703125e-01 -3.244331e+01 -9.753197e+01
293 5.722656e-01 -3.233709e+01 -9.772330e+01
294 5.742188e-01 -3.202665e+01 -9.789877e+01
295 5.761719e-01 -3.183587e+01 -9.805843e+01
296 5.781250e-01 -3.175207e+01 -9.820240e+01
297 5.800781e-01 -3.206598e+01 -9.833070e+01
298 5.820312e-01 -3.213130e+01 -9.844131e+01
299 5.839844e-01 -3.260234e+01 -9.853900e+01
300 5.859375e-01 -3.280532e+01 -9.862148e+01
301 5.878906e-01 -3.306511e+01 -9.868881e+01
302 5.898438e-01 -3.370452e+01 -9.874126e+01
303 5.917969e-01 -3.405451e+01 -9.877901e+01
304 5.937500e-01 -3.444847e+01 -9.880206e+01
305 5.957031e-01 -3.523914e+01 -9.881162e+01
306 5.976562e-01 -3.572489e+01 -9.880749e+01
307 5.996094e-01 -3.623545e+01 -9.879001e+01
308 6.015625e-01 -3.707359e+01 -9.875954e+01
309 6.035156e-01 -3.752569e+01 -9.871704e+01
310 6.054688e-01 -3.793775e+01 -9.866418e+01
311 6.074219e-01 -3.866925e+01 -9.859951e+01
312 6.093750e-01 -3.898969e+01 -9.852493e+01
313 6.113281e-01 -3.925133e+01 -9.844116e+01
314 6.132812e-01 -3.979554e+01 -9.834885e+01
315 6.152344e-01 -3.987579e+01 -9.824873e+01
316 6.171875e-01 -4.005821e+01 -9.814337e+01
317 6.191406e-01 -3.989975e+01 -9.802883e+01
318 6.210938e-01 -3.963201e+01 -9.790731e+01
319 6.230469e-01 -3.924781e+01 -9.777881e+01
320 6.250000e-01 -3.911417e+01 -9.764336e+01
321 6.269531e-01 -3.844576e+01 -9.750334e+01
322 6.289062e-01 -3.803825e+01 -9.735278e+01
323 6.308594e-01 -3.708129e+01 -9.719392e+01
324 6.328125e-01 -3.599747e+01 -9.702607e+01
325 6.347656e-01 -3.478820e+01 -9.684857e+01
326 6.367188e-01 -3.386496e+01 -9.666061e+01
327 6.386719e-01 -3.242358e+01 -9.646570e+01
328 6.406250e-01 -3.131389e+01 -9.625481e+01
329 6.425781e-01 -2.967401e+01 -9.603092e+01
330 6.445312e-01 -2.795442e+01 -9.579307e+01
331 6.464844e-01 -2.660274e+01 -9.554023e+01
332 6.484375e-01 -2.478701e+01 -9.527165e+01
333 6.503906e-01 -2.295190e+01 -9.499215e+01
334 6.523438e-01 -2.155127e+01 -9.468923e+01
335 6.542969e-01 -1.970520e+01 -9.436791e+01
336 6.562500e-01 -1.788654e+01 -9.402733e+01
337 6.582031e-01 -1.654778e+01 -9.366702e+01
338 6.601562e-01 -1.482312e+01 -9.328664e+01
339 6.621094e-01 -1.317235e+01 -9.289421e+01
340 6.640625e-01 -1.204161e+01 -9.247304e+01
341 6.660156e-01 -1.051683e+01 -9.203084e+01
342 6.679688e-01 -9.071044e+00 -9.156731e+01
343 6.699219e-01 -8.139014e+00 -9.108253e+01
344 6.718750e-01 -6.841722e+00 -9.057661e+01
345 6.738281e-01 -6.106919e+00 -9.006081e+01
346 6.757812e-01 -5.028818e+00 -8.951367e+01
347 6.777344e-01 -4.082304e+00 -8.894614e+01
348 6.796875e-01 -3.274823e+00 -8.835862e+01
349 6.816406e-01 -3.054779e+00 -8.775168e+01
350 6.835938e-01 -2.534873e+00 -8.713868e+01
351 6.855469e-01 -2.604808e+00 -8.649464e+01
352 6.875000e-01 -2.344663e+00 -8.583259e+01
353 6.894531e-01 -2.215110e+00 -8.515307e+01
354 6.914062e-01 -2.201709e+00 -8.445688e+01
355 6.933594e-01 -2.707174e+00 -8.374437e+01
356 6.953125e-01 -2.834135e+00 -8.303137e+01
357 6.972656e-01 -3.455405e+00 -8.228876e+01
358 6.992188e-01 -3.665093e+00 -8.153204e+01
359 7.011719e-01 -3.911719e+00 -8.076205e+01
360 7.031250e-01 -4.602333e+00 -7.997940e+01
361 7.050781e-01 -4.851428e+00 -7.918519e+01
362 7.070312e-01 -5.102061e+00 -7.839668e+01
363 7.089844e-01 -5.778453e+00 -7.758106e+01
364 7.109375e-01 -5.980195e+00 -7.675515e+01
365 7.128906e-01 -6.156246e+00 -7.592006e+01
366 7.148438e-01 -6.733342e+00 -7.507634e+01
367 7.167969e-01 -6.851107e+00 -7.422424e+01
368 7.187500e-01 -6.939577e+00 -7.338154e+01
369 7.207031e-01 -7.417239e+00 -7.251360e+01
370 7.226562e-01 -7.395424e+00 -7.163842e+01
371 7.246094e-01 -7.335527e+00 -7.075610e+01
372 7.265625e-01 -7.662527e+00 -6.986705e+01
373 7.285156e-01 -7.514922e+00 -6.897193e+01
374 7.304688e-01 -7.775149e+00 -6.808875e+01
375 7.324219e-01 -7.565700e+00 -6.718093e+01
376 7.343750e-01 -7.320085e+00 -6.626690e+01
377 7.363281e-01 -7.037102e+00 -6.534680e+01
378 7.382812e-01 -7.131598e+00 -6.442031e+01
379 7.402344e-01 -6.748079e+00 -6.350656e+01
380 7.421875e-01 -6.721401e+00 -6.256787e+01
381 7.441406e-01 -6.182204e+00 -6.162268e+01
382 7.460938e-01 -5.601639e+00 -6.067084e+01
383 7.480469e-01 -4.993733e+00 -5.971210e+01
384 7.500000e-01 -4.753927e+00 -5.874636e+01
385 7.519531e-01 -4.057645e+00 -5.779308e+01
386 7.539062e-01 -3.794474e+00 -5.681258e+01
387 7.558594e-01 -3.129633e+00 -5.582463e+01
388 7.578125e-01 -2.511675e+00 -5.482886e+01
389 7.597656e-01 -2.354567e+00 -5.382520e+01
390 7.617188e-01 -1.868751e+00 -5.281351e+01
391 7.636719e-01 -1.865010e+00 -5.181435e+01
392 7.656250e-01 -1.477256e+00 -5.078552e+01
393 7.675781e-01 -1.118865e+00 -4.974671e+01
394 7.695312e-01 -7.983125e-01 -4.869783e+01
395 7.714844e-01 -9.045094e-01 -4.763850e+01
396 7.734375e-01 -6.367375e-01 -4.658982e+01
397 7.753906e-01 -7.956434e-01 -4.550775e+01
398 7.773438e-01 -5.915154e-01 -4.441412e+01
399 7.792969e-01 -4.208275e-01 -4.330912e+01
400 7.812500e-01 -2.778509e-01 -4.219272e+01
401 7.832031e-01 -5.187917e-01 -4.106503e+01
402 7.851562e-01 -3.950132e-01 -3.995010e+01
403 7.871094e-01 -6.763717e-01 -3.880187e+01
404 7.890625e-01 -6.096466e-01 -3.764370e+01
405 7.910156e-01 -5.794713e-01 -3.647627e+01
406 7.929688e-01 -9.319279e-01 -3.529940e+01
407 7.949219e-01 -9.376715e-01 -3.411327e+01
408 7.968750e-01 -9.675977e-01 -3.294290e+01
409 7.988281e-01 -1.368974e+00 -3.173987e+01
410 8.007812e-01 -1.414530e+00 -3.052790e+01
411 8.027344e-01 -1.465145e+00 -2.930729e+01
412 8.046875e-01 -1.858744e+00 -2.807823e+01
413 8.066406e-01 -1.898038e+00 -2.684103e+01
414 8.085938e-01 -1.908168e+00 -2.562202e+01
415 8.105469e-01 -2.217776e+00 -2.437135e+01
416 8.125000e-01 -2.142276e+00 -2.311492e+01
417 8.144531e-01 -2.012235e+00 -2.185327e+01
418 8.164062e-01 -2.130993e+00 -2.058753e+01
419 8.183594e-01 -1.848985e+00 -1.931839e+01
420 8.203125e-01 -1.794804e+00 -1.807253e+01
421 8.222656e-01 -1.311093e+00 -1.679889e+01
422 8.242188e-01 -7.383028e-01 -1.552386e+01
423 8.261719e-01 -9.195044e-02 -1.424797e+01
424 8.281250e-01 3.203346e-01 -1.297166e+01
425 8.300781e-01 1.113585e+00 -1.172137e+01
426 8.320312e-01 1.661944e+00 -1.044531e+01
427 8.339844e-01 2.569653e+00 -9.169987e+00
428 8.359375e-01 3.520800e+00 -7.896115e+00
429 8.378906e-01 4.227066e+00 -6.624173e+00
430 8.398438e-01 5.247984e+00 -5.354500e+00
431 8.417969e-01 6.280098e+00 -4.113314e+00
432 8.437500e-01 7.036387e+00 -2.849249e+00
433 8.457031e-01 8.053559e+00 -1.588059e+00
434 8.476562e-01 9.017120e+00 -3.297721e-01
435 8.496094e-01 9.670465e+00 9.254413e-01
436 8.515625e-01 1.055213e+01 2.177090e+00
437 8.535156e-01 1.137966e+01 3.399672e+00
438 8.554688e-01 1.189971e+01 4.643933e+00
439 8.574219e-01 1.263765e+01 5.884264e+00
440 8.593750e-01 1.333704e+01 7.120314e+00
441 8.613281e-01 1.376663e+01 8.351784e+00
442 8.632812e-01 1.440432e+01 9.578794e+00
443 8.652344e-01 1.478000e+01 1.077625e+01
444 8.671875e-01 1.535861e+01 1.199397e+01
445 8.691406e-01 1.590006e+01 1.320694e+01
446 8.710938e-01 1.639676e+01 1.441542e+01
447 8.730469e-01 1.664235e+01 1.561968e+01
448 8.750000e-01 1.705927e+01 1.679558e+01
449 8.769531e-01 1.723744e+01 1.799243e+01
450 8.789062e-01 1.758858e+01 1.918606e+01
451 8.808594e-01 1.790629e+01 2.037679e+01
452 8.828125e-01 1.819601e+01 2.156482e+01
453 8.847656e-01 1.828983e+01 2.275042e+01
454 8.867188e-01 1.855454e+01 2.390958e+01
455 8.886719e-01 1.864021e+01 2.509058e+01
456 8.906250e-01 1.889489e+01 2.626934e+01
457 8.925781e-01 1.913816e+01 2.744579e+01
458 8.945312e-01 1.921844e+01 2.862013e+01
459 8.964844e-01 1.944044e+01 2.979227e+01
460 8.984375e-01 1.964027e+01 3.093810e+01
461 9.003906e-01 1.967664e+01 3.210524e+01
462 9.023438e-01 1.982605e+01 3.326964e+01
463 9.042969e-01 1.994137e+01 3.443114e+01
464 9.062500e-01 1.990516e+01 3.558928e+01
465 9.082031e-01 1.996047e+01 3.674389e+01
466 9.101562e-01 1.997884e+01 3.787140e+01
467 9.121094e-01 1.986363e+01 3.901869e+01
468 9.140625e-01 1.982371e+01 4.016194e+01
469 9.160156e-01 1.974571e+01 4.130057e+01
470 9.179688e-01 1.954855e+01 4.243441e+01
471 9.199219e-01 1.940870e+01 4.356289e+01
472 9.218750e-01 1.916557e+01 4.466250e+01
473 9.238281e-01 1.897153e+01 4.577835e+01
474 9.257812e-01 1.875081e+01 4.688711e+01
475 9.277344e-01 1.850985e+01 4.798828e+01
476 9.296875e-01 1.820400e+01 4.908082e+01
477 9.316406e-01 1.794282e+01 5.014145e+01
478 9.335938e-01 1.763469e+01 5.121397e+01
479 9.355469e-01 1.736724e+01 5.227604e+01
480 9.375000e-01 1.710153e+01 5.332692e+01
481 9.394531e-01 1.684171e+01 5.436558e+01
482 9.414062e-01 1.657565e+01 5.539177e+01
483 9.433594e-01 1.634926e+01 5.638500e+01
484 9.453125e-01 1.614664e+01 5.738728e+01
485 9.472656e-01 1.598880e+01 5.837784e+01
486 9.492188e-01 1.587551e+01 5.935671e+01
487 9.511719e-01 1.582282e+01 6.032423e+01
488 9.531250e-01 1.583570e+01 6.128038e+01
489 9.550781e-01 1.593462e+01 6.220634e+01
490 9.570312e-01 1.615678e+01 6.314101e+01
491 9.589844e-01 1.648285e+01 6.406513e+01
492 9.609375e-01 1.695633e+01 6.497870e+01
493 9.628906e-01 1.762161e+01 6.588175e+01
494 9.648438e-01 1.843984e+01 6.677447e+01
495 9.667969e-01 1.945278e+01 6.763905e+01
496 9.687500e-01 2.070328e+01 6.851178e+01
497 9.707031e-01 2.211953e+01 6.937479e+01
498 9.726562e-01 2.373533e+01 7.022813e+01
499 9.746094e-01 2.558826e+01 7.107178e+01
500 9.765625e-01 2.757893e+01 7.190571e+01
501 9.785156e-01 2.978127e+01 7.271298e+01
502 9.804688e-01 3.207397e+01 7.352695e+01
503 9.824219e-01 3.448684e+01 7.433066e+01
504 9.843750e-01 3.699144e+01 7.512414e+01
505 9.863281e-01 3.962370e+01 7.590742e+01
506 9.882812e-01 4.223037e+01 7.666473e+01
507 9.902344e-01 4.492148e+01 7.742769e+01
508 9.921875e-01 4.752385e+01 7.818018e+01
509 9.941406e-01 5.007612e+01 7.892177e+01
510 9.960938e-01 5.254892e+01 7.965200e+01
511 9.980469e-01 5.499962e+01 8.037070e+01